Workbook

Sheet 基础销量预测-计划端
A1: 美国 | B1: 大盘参数 | E1: 份额调整参数 | H1: 份额调整边界 | K1: 美国bsr系数（上半年） | P1: 加拿大bsr系数（上半年）
B2: 2025年度大盘同比 | C2: 0.050340992 | E2: 高销量产品月度延续权重 | F2: 0.25 | H2: 高销量产品下限 | I2: -0.3 | K2: 组别 | L2: 24年同比 | M2: 25年同比 | N2: 2026年同比 | P2: 组别 | Q2: 25年同比 | R2: 2026年同比
B3: 2026H1大盘同比 | C3: 0.028105839 | D3: =(C3-C2)/C2 | E3: 低销量产品月度延续权重 | F3: 0.25 | H3: 高销量产品上限 | I3: 0.3 | K3: 1 | L3: {=_xlfn.XLOOKUP($K3,'BSR底表-美国'!$A:$A,'BSR底表-美国'!F:F)} | M3: {=_xlfn.XLOOKUP($K3,'BSR底表-美国'!$A:$A,'BSR底表-美国'!G:G)} | N3: {=_xlfn.XLOOKUP($K3,'BSR底表-美国'!$A:$A,'BSR底表-美国'!H:H)} | P3: 1 | Q3: {=_xlfn.XLOOKUP($P3,'BSR底表-加拿大'!$A:$A,'BSR底表-加拿大'!E:E)} | R3: {=_xlfn.XLOOKUP($P3,'BSR底表-加拿大'!$A:$A,'BSR底表-加拿大'!F:F)}
A4: 26较25年增降幅，预测27年大盘增降幅 | B4: 2027大盘基准增速 | C4: =D4 | D4: =C3*(1+D3) | H4: 低销量产品上下限 | I4: 0.15 | K4: 2-5 | L4: {=_xlfn.XLOOKUP($K4,'BSR底表-美国'!$A:$A,'BSR底表-美国'!F:F)} | M4: {=_xlfn.XLOOKUP($K4,'BSR底表-美国'!$A:$A,'BSR底表-美国'!G:G)} | N4: {=_xlfn.XLOOKUP($K4,'BSR底表-美国'!$A:$A,'BSR底表-美国'!H:H)} | P4: 2-5 | Q4: {=_xlfn.XLOOKUP($P4,'BSR底表-加拿大'!$A:$A,'BSR底表-加拿大'!E:E)} | R4: {=_xlfn.XLOOKUP($P4,'BSR底表-加拿大'!$A:$A,'BSR底表-加拿大'!F:F)}
K5: 6-10 | L5: {=_xlfn.XLOOKUP($K5,'BSR底表-美国'!$A:$A,'BSR底表-美国'!F:F)} | M5: {=_xlfn.XLOOKUP($K5,'BSR底表-美国'!$A:$A,'BSR底表-美国'!G:G)} | N5: {=_xlfn.XLOOKUP($K5,'BSR底表-美国'!$A:$A,'BSR底表-美国'!H:H)} | P5: 6-10 | Q5: {=_xlfn.XLOOKUP($P5,'BSR底表-加拿大'!$A:$A,'BSR底表-加拿大'!E:E)} | R5: {=_xlfn.XLOOKUP($P5,'BSR底表-加拿大'!$A:$A,'BSR底表-加拿大'!F:F)}
A6: 加拿大 | B6: 大盘参数 | K6: 11-15 | L6: {=_xlfn.XLOOKUP($K6,'BSR底表-美国'!$A:$A,'BSR底表-美国'!F:F)} | M6: {=_xlfn.XLOOKUP($K6,'BSR底表-美国'!$A:$A,'BSR底表-美国'!G:G)} | N6: {=_xlfn.XLOOKUP($K6,'BSR底表-美国'!$A:$A,'BSR底表-美国'!H:H)} | P6: 11-15 | Q6: {=_xlfn.XLOOKUP($P6,'BSR底表-加拿大'!$A:$A,'BSR底表-加拿大'!E:E)} | R6: {=_xlfn.XLOOKUP($P6,'BSR底表-加拿大'!$A:$A,'BSR底表-加拿大'!F:F)}
B7: 2025年度大盘同比 | C7: 1.2258741 | K7: 16-20 | L7: {=_xlfn.XLOOKUP($K7,'BSR底表-美国'!$A:$A,'BSR底表-美国'!F:F)} | M7: {=_xlfn.XLOOKUP($K7,'BSR底表-美国'!$A:$A,'BSR底表-美国'!G:G)} | N7: {=_xlfn.XLOOKUP($K7,'BSR底表-美国'!$A:$A,'BSR底表-美国'!H:H)} | P7: 16-20 | Q7: {=_xlfn.XLOOKUP($P7,'BSR底表-加拿大'!$A:$A,'BSR底表-加拿大'!E:E)} | R7: {=_xlfn.XLOOKUP($P7,'BSR底表-加拿大'!$A:$A,'BSR底表-加拿大'!F:F)}
B8: 2026H1大盘同比 | C8: 0.39233709 | D8: =(C8-C7)/C7 | K8: 46 - 50 | L8: {=_xlfn.XLOOKUP($K8,'BSR底表-美国'!$A:$A,'BSR底表-美国'!F:F)} | M8: {=_xlfn.XLOOKUP($K8,'BSR底表-美国'!$A:$A,'BSR底表-美国'!G:G)} | N8: {=_xlfn.XLOOKUP($K8,'BSR底表-美国'!$A:$A,'BSR底表-美国'!H:H)} | P8: 46 - 50 | Q8: {=_xlfn.XLOOKUP($P8,'BSR底表-加拿大'!$A:$A,'BSR底表-加拿大'!E:E)} | R8: {=_xlfn.XLOOKUP($P8,'BSR底表-加拿大'!$A:$A,'BSR底表-加拿大'!F:F)}
A9: 26较25年增降幅，预测27年大盘降幅 | B9: 2027大盘基准增速 | C9: 0.12556623 | D9: =C8*(1+D8) | G9: 82255 | H9: =20381-9519 | K9: 51 - 80 | L9: {=_xlfn.XLOOKUP($K9,'BSR底表-美国'!$A:$A,'BSR底表-美国'!F:F)} | M9: {=_xlfn.XLOOKUP($K9,'BSR底表-美国'!$A:$A,'BSR底表-美国'!G:G)} | N9: {=_xlfn.XLOOKUP($K9,'BSR底表-美国'!$A:$A,'BSR底表-美国'!H:H)} | P9: 51 - 80 | Q9: {=_xlfn.XLOOKUP($P9,'BSR底表-加拿大'!$A:$A,'BSR底表-加拿大'!E:E)} | R9: {=_xlfn.XLOOKUP($P9,'BSR底表-加拿大'!$A:$A,'BSR底表-加拿大'!F:F)}
D10: =(C9-C8)/C8 | G10: =H9/G9 | H10: =1-G10
H15: 1、可调整BSR系数 2、使用4月稳定BSR目标排名 | I15: 实际6月已剔除大促销量 | AC15: PS：实际销量含PD，预测含PD，整体大盘同比未含PD
A16: 父msku | B16: 站点 | C16: 父ASIN | D16: 父体类型 | E16: 2025H1销量 | F16: 2026H1销量 | G16: 自身H1同比 | H16: 大盘H1&BSR排名增幅 | I16: 相对大盘增量变化 | J16: 月度占比份额调整 | K16: 保守系数 | L16: 乐观系数 | M16: 1月保守 | N16: 1月正常 | O16: 1月乐观 | P16: 2月保守 | Q16: 2月正常 | R16: 2月乐观 | S16: 3月保守 | T16: 3月正常 | U16: 3月乐观 | V16: 4月保守 | W16: 4月正常 | X16: 4月乐观 | Y16: 5月保守 | Z16: 5月正常 | AA16: 5月乐观 | AB16: 6月保守 | AC16: 6月正常 | AD16: 6月乐观 | AE16: H1保守 | AF16: H1正常 | AG16: H1乐观 | AH16: 2027年1月 | AI16: 2027年2月 | AJ16: 2027年3月 | AK16: 2027年4月 | AL16: 2027年5月 | AM16: 2027年6月 | AN16: 1月正常+ | AO16: 2月正常+ | AP16: 3月正常+ | AQ16: 4月正常+ | AR16: 5月正常+ | AS16: 6月正常+ | AT16: 27年1-6月 | AU16: 26年1-6月 | AX16: 2月增幅 | AY16: 3月增幅 | AZ16: 4月增幅 | BA16: 5月增幅 | BB16: 6月增幅 | BC16: 历史1月销量 | BD16: 历史2月销量 | BE16: 历史3月销量 | BF16: 历史4月销量 | BG16: 历史5月销量 | BH16: 历史6月销量
A17: {=_xlfn.XLOOKUP(C17,'产品基础信息'!B:B,'产品基础信息'!C:C)} | B17: US | C17: B0CSKDP26Z | D17: 高销量产品 | E17: =SUM('历史月度销量'!AZ3:BE3) | F17: =SUM(P34:U34) | G17: =IF(E17>0,F17/E17-1,"") | H17: =$C$4*0.5+_xlfn.XLOOKUP(AK17,$K$2:$K$9,$M$2:$M$9)*0.2+_xlfn.XLOOKUP(AK17,$K$2:$K$9,$N$2:$N$9)*0.3 | I17: =IF(E17>0,(1+G17)/(1+H17)-1,"") | J17: =IF(D17="低销量产品",MIN($I$4,I17*$F$3),MIN($I$3,I17*$F$2)) | K17: 0.85 | L17: 1.18 | M17: =ROUND(N17*$K17,0) | N17: =ROUND(P34*(1+$H$52)*(1+$J17),0) | O17: =ROUND(N17*$L17,0) | P17: =ROUND(Q17*$K17,0) | Q17: =ROUND(Q34*(1+$H$53)*(1+$J17),0) | R17: =ROUND(Q17*$L17,0) | S17: =ROUND(T17*$K17,0) | T17: =ROUND(R34*(1+$H$54)*(1+$J17),0) | U17: =ROUND(T17*$L17,0) | V17: =ROUND(W17*$K17,0) | W17: =ROUND(S34*(1+$H$55)*(1+$J17),0) | X17: =ROUND(W17*$L17,0) | Y17: =ROUND(Z17*$K17,0) | Z17: =ROUND(T34*(1+$H$56)*(1+$J17),0) | AA17: =ROUND(Z17*$L17,0) | AB17: =ROUND(AC17*$K17,0) | AC17: =ROUND(W34*(1+$H$57)*(1+$J17),0) | AD17: =ROUND(AC17*$L17,0) | AE17: =SUM(M17,P17,S17,V17,Y17,AB17) | AF17: =SUM(N17,Q17,T17,W17,Z17,AC17) | AG17: =SUM(O17,R17,U17,X17,AA17,AD17) | AH17: 16-20 | AI17: 16-20 | AJ17: 6-10 | AK17: 6-10 | AL17: 6-10 | AM17: 6-10 | AN17: =N17 | AO17: =Q17 | AP17: =T17 | AQ17: =W17 | AR17: =Z17 | AS17: =AC17 | AT17: =SUM(AN17:AS17) | AU17: =SUM(BC17:BH17) | AV17: =AT17-AU17 | AW17: =(AT17-AU17)/AU17 | AX17: =IFERROR((AO17-AN17)/AN17,"") | AY17: =IFERROR((AP17-AO17)/AO17,"") | AZ17: =IFERROR((AQ17-AP17)/AP17,"") | BA17: =IFERROR((AR17-AQ17)/AQ17,"") | BB17: =IFERROR((AS17-AR17)/AR17,"") | BC17: =P34 | BD17: =Q34 | BE17: =R34 | BF17: =S34 | BG17: =T34 | BH17: =W34
A18: {=_xlfn.XLOOKUP(C18,'产品基础信息'!B:B,'产品基础信息'!C:C)} | B18: US | C18: B0BSKX7ZHN | D18: 高销量产品 | E18: =SUM('历史月度销量'!AZ4:BE4) | F18: =SUM(P35:U35) | G18: =IF(E18>0,F18/E18-1,"") | H18: =$C$4*0.5+_xlfn.XLOOKUP(AK18,$K$2:$K$9,$M$2:$M$9)*0.2+_xlfn.XLOOKUP(AK18,$K$2:$K$9,$N$2:$N$9)*0.3 | I18: =IF(E18>0,(1+G18)/(1+H18)-1,"") | J18: =IF(D18="低销量产品",MIN($I$4,I18*$F$3),MIN($I$3,I18*$F$2)) | K18: 0.92 | L18: 1.1 | M18: =ROUND(N18*$K18,0) | N18: =ROUND(P35*(1+$H$52)*(1+$J18),0) | O18: =ROUND(N18*$L18,0) | P18: =ROUND(Q18*$K18,0) | Q18: =ROUND(Q35*(1+$H$53)*(1+$J18),0) | R18: =ROUND(Q18*$L18,0) | S18: =ROUND(T18*$K18,0) | T18: =ROUND(R35*(1+$H$54)*(1+$J18),0) | U18: =ROUND(T18*$L18,0) | V18: =ROUND(W18*$K18,0) | W18: =ROUND(S35*(1+$H$55)*(1+$J18),0) | X18: =ROUND(W18*$L18,0) | Y18: =ROUND(Z18*$K18,0) | Z18: =ROUND(T35*(1+$H$56)*(1+$J18),0) | AA18: =ROUND(Z18*$L18,0) | AB18: =ROUND(AC18*$K18,0) | AC18: =ROUND(W35*(1+$H$57)*(1+$J18),0) | AD18: =ROUND(AC18*$L18,0) | AE18: =SUM(M18,P18,S18,V18,Y18,AB18) | AF18: =SUM(N18,Q18,T18,W18,Z18,AC18) | AG18: =SUM(O18,R18,U18,X18,AA18,AD18) | AH18: 11-15 | AI18: 6-10 | AJ18: 6-10 | AK18: 6-10 | AL18: 6-10 | AM18: 6-10 | AN18: =N18 | AO18: =Q18 | AP18: =T18 | AQ18: =W18 | AR18: =Z18 | AS18: =AC18 | AT18: =SUM(AN18:AS18) | AU18: =SUM(BC18:BH18) | AV18: =AT18-AU18 | AW18: =(AT18-AU18)/AU18 | AX18: =IFERROR((AO18-AN18)/AN18,"") | AY18: =IFERROR((AP18-AO18)/AO18,"") | AZ18: =IFERROR((AQ18-AP18)/AP18,"") | BA18: =IFERROR((AR18-AQ18)/AQ18,"") | BB18: =IFERROR((AS18-AR18)/AR18,"") | BC18: =P35 | BD18: =Q35 | BE18: =R35 | BF18: =S35 | BG18: =T35 | BH18: =W35
A19: {=_xlfn.XLOOKUP(C19,'产品基础信息'!B:B,'产品基础信息'!C:C)} | B19: US | C19: B0B2PCVNYJ | D19: 高销量产品 | E19: =SUM('历史月度销量'!AZ5:BE5) | F19: =SUM(P36:U36) | G19: =IF(E19>0,F19/E19-1,"") | H19: =$C$4*0.5+_xlfn.XLOOKUP(AK19,$K$2:$K$9,$M$2:$M$9)*0.2+_xlfn.XLOOKUP(AK19,$K$2:$K$9,$N$2:$N$9)*0.3 | I19: =IF(E19>0,(1+G19)/(1+H19)-1,"") | J19: =IF(D19="低销量产品",MIN($I$4,I19*$F$3),MIN($I$3,I19*$F$2)) | K19: 0.92 | L19: 1.1 | M19: =ROUND(N19*$K19,0) | N19: =ROUND(P36*(1+$H$52)*(1+$J19),0) | O19: =ROUND(N19*$L19,0) | P19: =ROUND(Q19*$K19,0) | Q19: =ROUND(Q36*(1+$H$53)*(1+$J19),0) | R19: =ROUND(Q19*$L19,0) | S19: =ROUND(T19*$K19,0) | T19: =ROUND(R36*(1+$H$54)*(1+$J19),0) | U19: =ROUND(T19*$L19,0) | V19: =ROUND(W19*$K19,0) | W19: =ROUND(S36*(1+$H$55)*(1+$J19),0) | X19: =ROUND(W19*$L19,0) | Y19: =ROUND(Z19*$K19,0) | Z19: =ROUND(T36*(1+$H$56)*(1+$J19),0) | AA19: =ROUND(Z19*$L19,0) | AB19: =ROUND(AC19*$K19,0) | AC19: =ROUND(W36*(1+$H$57)*(1+$J19),0) | AD19: =ROUND(AC19*$L19,0) | AE19: =SUM(M19,P19,S19,V19,Y19,AB19) | AF19: =SUM(N19,Q19,T19,W19,Z19,AC19) | AG19: =SUM(O19,R19,U19,X19,AA19,AD19) | AH19: 1 | AI19: 1 | AJ19: 1 | AK19: 1 | AL19: 1 | AM19: 1 | AN19: =N19 | AO19: =Q19 | AP19: =T19 | AQ19: =W19 | AR19: =Z19 | AS19: =AC19 | AT19: =SUM(AN19:AS19) | AU19: =SUM(BC19:BH19) | AV19: =AT19-AU19 | AW19: =(AT19-AU19)/AU19 | AX19: =IFERROR((AO19-AN19)/AN19,"") | AY19: =IFERROR((AP19-AO19)/AO19,"") | AZ19: =IFERROR((AQ19-AP19)/AP19,"") | BA19: =IFERROR((AR19-AQ19)/AQ19,"") | BB19: =IFERROR((AS19-AR19)/AR19,"") | BC19: =P36 | BD19: =Q36 | BE19: =R36 | BF19: =S36 | BG19: =T36 | BH19: =W36
A20: {=_xlfn.XLOOKUP(C20,'产品基础信息'!B:B,'产品基础信息'!C:C)} | B20: US | C20: B0CCJ2MH3N | D20: 高销量产品 | E20: =SUM('历史月度销量'!AZ6:BE6) | F20: =SUM(P37:U37) | G20: =IF(E20>0,F20/E20-1,"") | H20: =$C$4*0.5+_xlfn.XLOOKUP(AK20,$K$2:$K$9,$M$2:$M$9)*0.2+_xlfn.XLOOKUP(AK20,$K$2:$K$9,$N$2:$N$9)*0.3 | I20: =IF(E20>0,(1+G20)/(1+H20)-1,"") | J20: =IF(D20="低销量产品",MIN($I$4,I20*$F$3),MIN($I$3,I20*$F$2)) | K20: 0.92 | L20: 1.1 | M20: =ROUND(N20*$K20,0) | N20: =ROUND(P37*(1+$H$52)*(1+$J20),0) | O20: =ROUND(N20*$L20,0) | P20: =ROUND(Q20*$K20,0) | Q20: =ROUND(Q37*(1+$H$53)*(1+$J20),0) | R20: =ROUND(Q20*$L20,0) | S20: =ROUND(T20*$K20,0) | T20: =ROUND(R37*(1+$H$54)*(1+$J20),0) | U20: =ROUND(T20*$L20,0) | V20: =ROUND(W20*$K20,0) | W20: =ROUND(S37*(1+$H$55)*(1+$J20),0) | X20: =ROUND(W20*$L20,0) | Y20: =ROUND(Z20*$K20,0) | Z20: =ROUND(T37*(1+$H$56)*(1+$J20),0) | AA20: =ROUND(Z20*$L20,0) | AB20: =ROUND(AC20*$K20,0) | AC20: =ROUND(W37*(1+$H$57)*(1+$J20),0) | AD20: =ROUND(AC20*$L20,0) | AE20: =SUM(M20,P20,S20,V20,Y20,AB20) | AF20: =SUM(N20,Q20,T20,W20,Z20,AC20) | AG20: =SUM(O20,R20,U20,X20,AA20,AD20) | AH20: 2-5 | AI20: 2-5 | AJ20: 2-5 | AK20: 2-5 | AL20: 2-5 | AM20: 2-5 | AN20: =N20 | AO20: =Q20 | AP20: =T20 | AQ20: =W20 | AR20: =Z20 | AS20: =AC20 | AT20: =SUM(AN20:AS20) | AU20: =SUM(BC20:BH20) | AV20: =AT20-AU20 | AW20: =(AT20-AU20)/AU20 | AX20: =IFERROR((AO20-AN20)/AN20,"") | AY20: =IFERROR((AP20-AO20)/AO20,"") | AZ20: =IFERROR((AQ20-AP20)/AP20,"") | BA20: =IFERROR((AR20-AQ20)/AQ20,"") | BB20: =IFERROR((AS20-AR20)/AR20,"") | BC20: =P37 | BD20: =Q37 | BE20: =R37 | BF20: =S37 | BG20: =T37 | BH20: =W37
A21: {=_xlfn.XLOOKUP(C21,'产品基础信息'!B:B,'产品基础信息'!C:C)} | B21: US | C21: B0D17P9F9S | D21: 低销量产品 | E21: =SUM('历史月度销量'!AZ7:BE7) | F21: =SUM(P38:U38) | G21: =IF(E21>0,F21/E21-1,"") | H21: =$C$4*0.5+_xlfn.XLOOKUP(AK21,$K$2:$K$9,$M$2:$M$9)*0.2+_xlfn.XLOOKUP(AK21,$K$2:$K$9,$N$2:$N$9)*0.3 | I21: =IF(E21>0,(1+G21)/(1+H21)-1,"") | J21: 0 | K21: 0.68 | L21: 1.3 | M21: =ROUND(N21*$K21,0) | N21: =ROUND(P38*(1+$H$52)*(1+$J21),0) | O21: =ROUND(N21*$L21,0) | P21: =ROUND(Q21*$K21,0) | Q21: =ROUND(Q38*(1+$H$53)*(1+$J21),0) | R21: =ROUND(Q21*$L21,0) | S21: =ROUND(T21*$K21,0) | T21: =ROUND(R38*(1+$H$54)*(1+$J21),0) | U21: =ROUND(T21*$L21,0) | V21: =ROUND(W21*$K21,0) | W21: =ROUND(S38*(1+$H$55)*(1+$J21),0) | X21: =ROUND(W21*$L21,0) | Y21: =ROUND(Z21*$K21,0) | Z21: =ROUND(T38*(1+$H$56)*(1+$J21),0) | AA21: =ROUND(Z21*$L21,0) | AB21: =ROUND(AC21*$K21,0) | AC21: =ROUND(W38*(1+$H$57)*(1+$J21),0) | AD21: =ROUND(AC21*$L21,0) | AE21: =SUM(M21,P21,S21,V21,Y21,AB21) | AF21: =SUM(N21,Q21,T21,W21,Z21,AC21) | AG21: =SUM(O21,R21,U21,X21,AA21,AD21) | AJ21: 51 - 80 | AK21: 46 - 50 | AL21: 46 - 50 | AM21: 46 - 50 | AN21: =N21 | AO21: =Q21 | AP21: =T21 | AQ21: =W21 | AR21: =Z21 | AS21: =AC21 | AT21: =SUM(AN21:AS21) | AU21: =SUM(BC21:BH21) | AV21: =AT21-AU21 | AW21: =(AT21-AU21)/AU21 | AX21: =IFERROR((AO21-AN21)/AN21,"") | AY21: =IFERROR((AP21-AO21)/AO21,"") | AZ21: =IFERROR((AQ21-AP21)/AP21,"") | BA21: =IFERROR((AR21-AQ21)/AQ21,"") | BB21: =IFERROR((AS21-AR21)/AR21,"") | BC21: =P38 | BD21: =Q38 | BE21: =R38 | BF21: =S38 | BG21: =T38 | BH21: =W38
A22: {=_xlfn.XLOOKUP(C22,'产品基础信息'!B:B,'产品基础信息'!C:C)} | B22: US | C22: B0D4PHQJYJ | D22: 低销量产品 | E22: =SUM('历史月度销量'!AZ8:BE8) | F22: =SUM(P39:U39) | G22: =IF(E22>0,F22/E22-1,"") | H22: =$C$4*0.5+_xlfn.XLOOKUP(AK22,$K$2:$K$9,$M$2:$M$9)*0.2+_xlfn.XLOOKUP(AK22,$K$2:$K$9,$N$2:$N$9)*0.3 | I22: =IF(E22>0,(1+G22)/(1+H22)-1,"") | J22: 0 | K22: 0.68 | L22: 1.3 | M22: =ROUND(N22*$K22,0) | N22: =ROUND(P39*(1+$H$52)*(1+$J22),0) | O22: =ROUND(N22*$L22,0) | P22: =ROUND(Q22*$K22,0) | Q22: =ROUND(Q39*(1+$H$53)*(1+$J22),0) | R22: =ROUND(Q22*$L22,0) | S22: =ROUND(T22*$K22,0) | T22: =ROUND(R39*(1+$H$54)*(1+$J22),0) | U22: =ROUND(T22*$L22,0) | V22: =ROUND(W22*$K22,0) | W22: =ROUND(S39*(1+$H$55)*(1+$J22),0) | X22: =ROUND(W22*$L22,0) | Y22: =ROUND(Z22*$K22,0) | Z22: =ROUND(T39*(1+$H$56)*(1+$J22),0) | AA22: =ROUND(Z22*$L22,0) | AB22: =ROUND(AC22*$K22,0) | AC22: =ROUND(W39*(1+$H$57)*(1+$J22),0) | AD22: =ROUND(AC22*$L22,0) | AE22: =SUM(M22,P22,S22,V22,Y22,AB22) | AF22: =SUM(N22,Q22,T22,W22,Z22,AC22) | AG22: =SUM(O22,R22,U22,X22,AA22,AD22) | AJ22: 51 - 80 | AK22: 46 - 50 | AL22: 46 - 50 | AM22: 46 - 50 | AN22: =N22 | AO22: =Q22 | AP22: =T22 | AQ22: =W22 | AR22: =Z22 | AS22: =AC22 | AT22: =SUM(AN22:AS22) | AU22: =SUM(BC22:BH22) | AV22: =AT22-AU22 | AW22: =(AT22-AU22)/AU22 | AX22: =IFERROR((AO22-AN22)/AN22,"") | AY22: =IFERROR((AP22-AO22)/AO22,"") | AZ22: =IFERROR((AQ22-AP22)/AP22,"") | BA22: =IFERROR((AR22-AQ22)/AQ22,"") | BB22: =IFERROR((AS22-AR22)/AR22,"") | BC22: =P39 | BD22: =Q39 | BE22: =R39 | BF22: =S39 | BG22: =T39 | BH22: =W39
A23: {=_xlfn.XLOOKUP(C23,'产品基础信息'!B:B,'产品基础信息'!C:C)} | B23: US | C23: B0FWJY4CCQ | D23: 低销量产品 | E23: =SUM('历史月度销量'!AZ9:BE9) | F23: =SUM(P40:U40) | G23: =IF(E23>0,F23/E23-1,"") | H23: =$C$4*0.5+_xlfn.XLOOKUP(AK23,$K$2:$K$9,$M$2:$M$9)*0.2+_xlfn.XLOOKUP(AK23,$K$2:$K$9,$N$2:$N$9)*0.3 | I23: =IF(E23>0,(1+G23)/(1+H23)-1,"") | J23: 0 | K23: 0.68 | L23: 1.2 | M23: =ROUND(N23*$K23,0) | N23: =ROUND(P40*(1+$H$52)*(1+$J23),0) | O23: =ROUND(N23*$L23,0) | P23: =ROUND(Q23*$K23,0) | Q23: =ROUND(Q40*(1+$H$53)*(1+$J23),0) | R23: =ROUND(Q23*$L23,0) | S23: =ROUND(T23*$K23,0) | T23: =ROUND(R40*(1+$H$54)*(1+$J23),0) | U23: =ROUND(T23*$L23,0) | V23: =ROUND(W23*$K23,0) | W23: =ROUND(S40*(1+$H$55)*(1+$J23),0) | X23: =ROUND(W23*$L23,0) | Y23: =ROUND(Z23*$K23,0) | Z23: =ROUND(T40*(1+$H$56)*(1+$J23),0) | AA23: =ROUND(Z23*$L23,0) | AB23: =ROUND(AC23*$K23,0) | AC23: =ROUND(W40*(1+$H$57)*(1+$J23),0) | AD23: =ROUND(AC23*$L23,0) | AE23: =SUM(M23,P23,S23,V23,Y23,AB23) | AF23: =SUM(N23,Q23,T23,W23,Z23,AC23) | AG23: =SUM(O23,R23,U23,X23,AA23,AD23) | AJ23: 51 - 80 | AK23: 46 - 50 | AL23: 46 - 50 | AM23: 46 - 50 | AN23: =N23 | AO23: =Q23 | AP23: =T23 | AQ23: =W23 | AR23: =Z23 | AS23: =AC23 | AT23: =SUM(AN23:AS23) | AU23: =SUM(BC23:BH23) | AV23: =AT23-AU23 | AW23: =(AT23-AU23)/AU23 | AX23: =IFERROR((AO23-AN23)/AN23,"") | AY23: =IFERROR((AP23-AO23)/AO23,"") | AZ23: =IFERROR((AQ23-AP23)/AP23,"") | BA23: =IFERROR((AR23-AQ23)/AQ23,"") | BB23: =IFERROR((AS23-AR23)/AR23,"") | BC23: =P40 | BD23: =Q40 | BE23: =R40 | BF23: =S40 | BG23: =T40 | BH23: =W40
A24: {=_xlfn.XLOOKUP(C24,'产品基础信息'!B:B,'产品基础信息'!C:C)} | B24: US | C24: B0DBPK9CTR | D24: 低销量产品 | E24: =SUM('历史月度销量'!AZ10:BE10) | F24: =SUM(P41:U41) | G24: =IF(E24>0,F24/E24-1,"") | H24: =$C$4*0.5+_xlfn.XLOOKUP(AK24,$K$2:$K$9,$M$2:$M$9)*0.2+_xlfn.XLOOKUP(AK24,$K$2:$K$9,$N$2:$N$9)*0.3 | I24: =IF(E24>0,(1+G24)/(1+H24)-1,"") | J24: 0 | K24: 0.68 | L24: 1.2 | M24: =ROUND(N24*$K24,0) | N24: =ROUND(P41*(1+$H$52)*(1+$J24),0) | O24: =ROUND(N24*$L24,0) | P24: =ROUND(Q24*$K24,0) | Q24: =ROUND(Q41*(1+$H$53)*(1+$J24),0) | R24: =ROUND(Q24*$L24,0) | S24: =ROUND(T24*$K24,0) | T24: =ROUND(R41*(1+$H$54)*(1+$J24),0) | U24: =ROUND(T24*$L24,0) | V24: =ROUND(W24*$K24,0) | W24: =ROUND(S41*(1+$H$55)*(1+$J24),0) | X24: =ROUND(W24*$L24,0) | Y24: =ROUND(Z24*$K24,0) | Z24: =ROUND(T41*(1+$H$56)*(1+$J24),0) | AA24: =ROUND(Z24*$L24,0) | AB24: =ROUND(AC24*$K24,0) | AC24: =ROUND(W41*(1+$H$57)*(1+$J24),0) | AD24: =ROUND(AC24*$L24,0) | AE24: =SUM(M24,P24,S24,V24,Y24,AB24) | AF24: =SUM(N24,Q24,T24,W24,Z24,AC24) | AG24: =SUM(O24,R24,U24,X24,AA24,AD24) | AJ24: 51 - 80 | AK24: 46 - 50 | AL24: 46 - 50 | AM24: 46 - 50 | AN24: =N24 | AO24: =Q24 | AP24: =T24 | AQ24: =W24 | AR24: =Z24 | AS24: =AC24 | AT24: =SUM(AN24:AS24) | AU24: =SUM(BC24:BH24) | AV24: =AT24-AU24 | AW24: =(AT24-AU24)/AU24 | AX24: =IFERROR((AO24-AN24)/AN24,"") | AY24: =IFERROR((AP24-AO24)/AO24,"") | AZ24: =IFERROR((AQ24-AP24)/AP24,"") | BA24: =IFERROR((AR24-AQ24)/AQ24,"") | BB24: =IFERROR((AS24-AR24)/AR24,"") | BC24: =P41 | BD24: =Q41 | BE24: =R41 | BF24: =S41 | BG24: =T41 | BH24: =W41
A25: {=_xlfn.XLOOKUP(C25,'产品基础信息'!B:B,'产品基础信息'!C:C)} | B25: US | C25: B0DBLYWHF4 | D25: 高销量产品 | E25: =SUM('历史月度销量'!AZ11:BE11) | F25: =SUM(P42:U42) | G25: =IF(E25>0,F25/E25-1,"") | H25: =$C$4*0.5+_xlfn.XLOOKUP(AK25,$K$2:$K$9,$M$2:$M$9)*0.2+_xlfn.XLOOKUP(AK25,$K$2:$K$9,$N$2:$N$9)*0.3 | I25: =IF(E25>0,(1+G25)/(1+H25)-1,"") | J25: 0 | K25: 0.68 | L25: 1.3 | M25: =ROUND(N25*$K25,0) | N25: =ROUND(P42*(1+$H$52)*(1+$J25),0) | O25: =ROUND(N25*$L25,0) | P25: =ROUND(Q25*$K25,0) | Q25: =ROUND(Q42*(1+$H$53)*(1+$J25),0) | R25: =ROUND(Q25*$L25,0) | S25: =ROUND(T25*$K25,0) | T25: =ROUND(R42*(1+$H$54)*(1+$J25),0) | U25: =ROUND(T25*$L25,0) | V25: =ROUND(W25*$K25,0) | W25: =ROUND(S42*(1+$H$55)*(1+$J25),0) | X25: =ROUND(W25*$L25,0) | Y25: =ROUND(Z25*$K25,0) | Z25: =ROUND(T42*(1+$H$56)*(1+$J25),0) | AA25: =ROUND(Z25*$L25,0) | AB25: =ROUND(AC25*$K25,0) | AC25: =ROUND(W42*(1+$H$57)*(1+$J25),0) | AD25: =ROUND(AC25*$L25,0) | AE25: =SUM(M25,P25,S25,V25,Y25,AB25) | AF25: =SUM(N25,Q25,T25,W25,Z25,AC25) | AG25: =SUM(O25,R25,U25,X25,AA25,AD25) | AJ25: 51 - 80 | AK25: 46 - 50 | AL25: 46 - 50 | AM25: 46 - 50 | AN25: =N25 | AO25: =Q25 | AP25: =T25 | AQ25: =W25 | AR25: =Z25 | AS25: =AC25 | AT25: =SUM(AN25:AS25) | AU25: =SUM(BC25:BH25) | AV25: =AT25-AU25 | AW25: =(AT25-AU25)/AU25 | AX25: =IFERROR((AO25-AN25)/AN25,"") | AY25: =IFERROR((AP25-AO25)/AO25,"") | AZ25: =IFERROR((AQ25-AP25)/AP25,"") | BA25: =IFERROR((AR25-AQ25)/AQ25,"") | BB25: =IFERROR((AS25-AR25)/AR25,"") | BC25: =P42 | BD25: =Q42 | BE25: =R42 | BF25: =S42 | BG25: =T42 | BH25: =W42
A26: {=_xlfn.XLOOKUP(C26,'产品基础信息'!B:B,'产品基础信息'!C:C)} | B26: CA | C26: B0CT5G5TVT | D26: 低销量产品 | E26: =SUM('历史月度销量'!AZ12:BE12) | F26: =SUM(P43:U43) | G26: =IF(E26>0,F26/E26-1,"") | H26: =$C$9*0.5+_xlfn.XLOOKUP(AK26,$P$3:$P$9,$R$3:$R$9)*0.5 | I26: =IF(E26>0,(1+G26)/(1+H26)-1,"") | J26: 0 | K26: 0.68 | L26: 1.3 | M26: =ROUND(N26*$K26,0) | N26: =ROUND(P43*(1+$H$52)*(1+$J26),0) | O26: =ROUND(N26*$L26,0) | P26: =ROUND(Q26*$K26,0) | Q26: =ROUND(Q43*(1+$H$53)*(1+$J26),0) | R26: =ROUND(Q26*$L26,0) | S26: =ROUND(T26*$K26,0) | T26: =ROUND(R43*(1+$H$54)*(1+$J26),0) | U26: =ROUND(T26*$L26,0) | V26: =ROUND(W26*$K26,0) | W26: =ROUND(S43*(1+$H$55)*(1+$J26),0) | X26: =ROUND(W26*$L26,0) | Y26: =ROUND(Z26*$K26,0) | Z26: =ROUND(T43*(1+$H$56)*(1+$J26),0) | AA26: =ROUND(Z26*$L26,0) | AB26: =ROUND(AC26*$K26,0) | AC26: =ROUND(W43*(1+$H$57)*(1+$J26),0) | AD26: =ROUND(AC26*$L26,0) | AE26: =SUM(M26,P26,S26,V26,Y26,AB26) | AF26: =SUM(N26,Q26,T26,W26,Z26,AC26) | AG26: =SUM(O26,R26,U26,X26,AA26,AD26) | AJ26: 1 | AK26: 1 | AL26: 1 | AM26: 1 | AN26: =N26 | AO26: =Q26 | AP26: =T26 | AQ26: =W26 | AR26: =Z26 | AS26: =AC26 | AT26: =SUM(AN26:AS26) | AU26: =SUM(BC26:BH26) | AV26: =AT26-AU26 | AW26: =(AT26-AU26)/AU26 | AX26: =IFERROR((AO26-AN26)/AN26,"") | AY26: =IFERROR((AP26-AO26)/AO26,"") | AZ26: =IFERROR((AQ26-AP26)/AP26,"") | BA26: =IFERROR((AR26-AQ26)/AQ26,"") | BB26: =IFERROR((AS26-AR26)/AR26,"") | BC26: =P43 | BD26: =Q43 | BE26: =R43 | BF26: =S43 | BG26: =T43 | BH26: =W43
A27: {=_xlfn.XLOOKUP(C27,'产品基础信息'!B:B,'产品基础信息'!C:C)} | B27: CA | C27: B0D3J2Q1JM | D27: 低销量产品 | E27: =SUM('历史月度销量'!AZ13:BE13) | F27: =SUM(P44:U44) | G27: =IF(E27>0,F27/E27-1,"") | H27: =$C$9*0.5+_xlfn.XLOOKUP(AK27,$P$3:$P$9,$R$3:$R$9)*0.5 | I27: =IF(E27>0,(1+G27)/(1+H27)-1,"") | J27: 0 | K27: 0.68 | L27: 1.3 | M27: =ROUND(N27*$K27,0) | N27: =ROUND(P44*(1+$H$52)*(1+$J27),0) | O27: =ROUND(N27*$L27,0) | P27: =ROUND(Q27*$K27,0) | Q27: =ROUND(Q44*(1+$H$53)*(1+$J27),0) | R27: =ROUND(Q27*$L27,0) | S27: =ROUND(T27*$K27,0) | T27: =ROUND(R44*(1+$H$54)*(1+$J27),0) | U27: =ROUND(T27*$L27,0) | V27: =ROUND(W27*$K27,0) | W27: =ROUND(S44*(1+$H$55)*(1+$J27),0) | X27: =ROUND(W27*$L27,0) | Y27: =ROUND(Z27*$K27,0) | Z27: =ROUND(T44*(1+$H$56)*(1+$J27),0) | AA27: =ROUND(Z27*$L27,0) | AB27: =ROUND(AC27*$K27,0) | AC27: =ROUND(W44*(1+$H$57)*(1+$J27),0) | AD27: =ROUND(AC27*$L27,0) | AE27: =SUM(M27,P27,S27,V27,Y27,AB27) | AF27: =SUM(N27,Q27,T27,W27,Z27,AC27) | AG27: =SUM(O27,R27,U27,X27,AA27,AD27) | AJ27: 2-5 | AK27: 2-5 | AL27: 2-5 | AM27: 2-5 | AN27: =N27 | AO27: =Q27 | AP27: =T27 | AQ27: =W27 | AR27: =Z27 | AS27: =AC27 | AT27: =SUM(AN27:AS27) | AU27: =SUM(BC27:BH27) | AV27: =AT27-AU27 | AW27: =(AT27-AU27)/AU27 | AX27: =IFERROR((AO27-AN27)/AN27,"") | AY27: =IFERROR((AP27-AO27)/AO27,"") | AZ27: =IFERROR((AQ27-AP27)/AP27,"") | BA27: =IFERROR((AR27-AQ27)/AQ27,"") | BB27: =IFERROR((AS27-AR27)/AR27,"") | BC27: =P44 | BD27: =Q44 | BE27: =R44 | BF27: =S44 | BG27: =T44 | BH27: =W44
A28: {=_xlfn.XLOOKUP(C28,'产品基础信息'!B:B,'产品基础信息'!C:C)} | B28: CA | C28: B0D3TS4TYR | D28: 低销量产品 | E28: =SUM('历史月度销量'!AZ14:BE14) | F28: =SUM(P45:U45) | G28: =IF(E28>0,F28/E28-1,"") | H28: =$C$9*0.5+_xlfn.XLOOKUP(AK28,$P$3:$P$9,$R$3:$R$9)*0.5 | I28: =IF(E28>0,(1+G28)/(1+H28)-1,"") | J28: 0 | K28: 0.68 | L28: 1.15 | M28: =ROUND(N28*$K28,0) | N28: =ROUND(P45*(1+$H$52)*(1+$J28),0) | O28: =ROUND(N28*$L28,0) | P28: =ROUND(Q28*$K28,0) | Q28: =ROUND(Q45*(1+$H$53)*(1+$J28),0) | R28: =ROUND(Q28*$L28,0) | S28: =ROUND(T28*$K28,0) | T28: =ROUND(R45*(1+$H$54)*(1+$J28),0) | U28: =ROUND(T28*$L28,0) | V28: =ROUND(W28*$K28,0) | W28: =ROUND(S45*(1+$H$55)*(1+$J28),0) | X28: =ROUND(W28*$L28,0) | Y28: =ROUND(Z28*$K28,0) | Z28: =ROUND(T45*(1+$H$56)*(1+$J28),0) | AA28: =ROUND(Z28*$L28,0) | AB28: =ROUND(AC28*$K28,0) | AC28: =ROUND(W45*(1+$H$57)*(1+$J28),0) | AD28: =ROUND(AC28*$L28,0) | AE28: =SUM(M28,P28,S28,V28,Y28,AB28) | AF28: =SUM(N28,Q28,T28,W28,Z28,AC28) | AG28: =SUM(O28,R28,U28,X28,AA28,AD28) | AJ28: 16-20 | AK28: 6-10 | AL28: 6-10 | AM28: 6-10 | AN28: =N28 | AO28: =Q28 | AP28: =T28 | AQ28: =W28 | AR28: =Z28 | AS28: =AC28 | AT28: =SUM(AN28:AS28) | AU28: =SUM(BC28:BH28) | AV28: =AT28-AU28 | AW28: =(AT28-AU28)/AU28 | AX28: =IFERROR((AO28-AN28)/AN28,"") | AY28: =IFERROR((AP28-AO28)/AO28,"") | AZ28: =IFERROR((AQ28-AP28)/AP28,"") | BA28: =IFERROR((AR28-AQ28)/AQ28,"") | BB28: =IFERROR((AS28-AR28)/AR28,"") | BC28: =P45 | BD28: =Q45 | BE28: =R45 | BF28: =S45 | BG28: =T45 | BH28: =W45
A29: {=_xlfn.XLOOKUP(C29,'产品基础信息'!B:B,'产品基础信息'!C:C)} | B29: CA | C29: B0DRFTHNM8 | D29: 低销量产品 | E29: =SUM('历史月度销量'!AZ15:BE15) | F29: =SUM(P46:U46) | G29: =IF(E29>0,F29/E29-1,"") | H29: =$C$9*0.5+_xlfn.XLOOKUP(AK29,$P$3:$P$9,$R$3:$R$9)*0.5 | I29: =IF(E29>0,(1+G29)/(1+H29)-1,"") | J29: 0 | K29: 0.68 | L29: 1.15 | M29: =ROUND(N29*$K29,0) | N29: =ROUND(P46*(1+$H$52)*(1+$J29),0) | O29: =ROUND(N29*$L29,0) | P29: =ROUND(Q29*$K29,0) | Q29: =ROUND(Q46*(1+$H$53)*(1+$J29),0) | R29: =ROUND(Q29*$L29,0) | S29: =ROUND(T29*$K29,0) | T29: =ROUND(R46*(1+$H$54)*(1+$J29),0) | U29: =ROUND(T29*$L29,0) | V29: =ROUND(W29*$K29,0) | W29: =ROUND(S46*(1+$H$55)*(1+$J29),0) | X29: =ROUND(W29*$L29,0) | Y29: =ROUND(Z29*$K29,0) | Z29: =ROUND(T46*(1+$H$56)*(1+$J29),0) | AA29: =ROUND(Z29*$L29,0) | AB29: =ROUND(AC29*$K29,0) | AC29: =ROUND(W46*(1+$H$57)*(1+$J29),0) | AD29: =ROUND(AC29*$L29,0) | AE29: =SUM(M29,P29,S29,V29,Y29,AB29) | AF29: =SUM(N29,Q29,T29,W29,Z29,AC29) | AG29: =SUM(O29,R29,U29,X29,AA29,AD29) | AJ29: 16-20 | AK29: 16-20 | AL29: 16-20 | AM29: 16-20 | AN29: =N29 | AO29: =Q29 | AP29: =T29 | AQ29: =W29 | AR29: =Z29 | AS29: =AC29 | AT29: =SUM(AN29:AS29) | AU29: =SUM(BC29:BH29) | AV29: =AT29-AU29 | AW29: =(AT29-AU29)/AU29 | AX29: =IFERROR((AO29-AN29)/AN29,"") | AY29: =IFERROR((AP29-AO29)/AO29,"") | AZ29: =IFERROR((AQ29-AP29)/AP29,"") | BA29: =IFERROR((AR29-AQ29)/AQ29,"") | BB29: =IFERROR((AS29-AR29)/AR29,"") | BC29: =P46 | BD29: =Q46 | BE29: =R46 | BF29: =S46 | BG29: =T46 | BH29: =W46
B32: 实际销量
A33: 父msku | B33: 站点 | C33: 父ASIN占位 | D33: 2025-01 | E33: 2025-02 | F33: 2025-03 | G33: 2025-04 | H33: 2025-05 | I33: 2025-06 | J33: 2025-07 | K33: 2025-08 | L33: 2025-09 | M33: 2025-10 | N33: 2025-11 | O33: 2025-12 | P33: 2026-01 | Q33: 2026-02 | R33: 2026-03 | S33: 2026-04 | T33: 2026-05 | U33: 46174 | V33: 2026-07 | W33: 2026-06实际销量
A34: {=_xlfn.XLOOKUP(C34,'产品基础信息'!B:B,'产品基础信息'!C:C)} | B34: US | C34: B0CSKDP26Z | D34: ='历史月度销量'!AZ3 | E34: ='历史月度销量'!BA3 | F34: ='历史月度销量'!BB3 | G34: ='历史月度销量'!BC3 | H34: ='历史月度销量'!BD3 | I34: ='历史月度销量'!BE3 | J34: ='历史月度销量'!BF3 | K34: ='历史月度销量'!BG3 | ... T34: ='历史月度销量'!BP3 | U34: =W34*0.87 | V34: {=_xlfn.XLOOKUP(C34,'26年实际销量'!A:A,'26年实际销量'!X:X)} | W34: 7492 | X34: =ROUND(I34/H34*T34,0) | Y34: =(U34-T34)/T34
A35: {=_xlfn.XLOOKUP(C35,'产品基础信息'!B:B,'产品基础信息'!C:C)} | B35: US | C35: B0BSKX7ZHN | D35: ='历史月度销量'!AZ4 | E35: ='历史月度销量'!BA4 | F35: ='历史月度销量'!BB4 | G35: ='历史月度销量'!BC4 | H35: ='历史月度销量'!BD4 | I35: ='历史月度销量'!BE4 | J35: ='历史月度销量'!BF4 | K35: ='历史月度销量'!BG4 | ... T35: ='历史月度销量'!BP4 | U35: =W35*0.87 | V35: {=_xlfn.XLOOKUP(C35,'26年实际销量'!A:A,'26年实际销量'!X:X)} | W35: 9323 | X35: =ROUND(I35/H35*T35,0) | Y35: =(U35-T35)/T35
A36: {=_xlfn.XLOOKUP(C36,'产品基础信息'!B:B,'产品基础信息'!C:C)} | B36: US | C36: B0B2PCVNYJ | D36: ='历史月度销量'!AZ5 | E36: ='历史月度销量'!BA5 | F36: ='历史月度销量'!BB5 | G36: ='历史月度销量'!BC5 | H36: ='历史月度销量'!BD5 | I36: ='历史月度销量'!BE5 | J36: ='历史月度销量'!BF5 | K36: ='历史月度销量'!BG5 | ... T36: ='历史月度销量'!BP5 | U36: =W36*0.87 | V36: {=_xlfn.XLOOKUP(C36,'26年实际销量'!A:A,'26年实际销量'!X:X)} | W36: 19707 | X36: =ROUND(I36/H36*T36,0) | Y36: =(U36-T36)/T36
A37: {=_xlfn.XLOOKUP(C37,'产品基础信息'!B:B,'产品基础信息'!C:C)} | B37: US | C37: B0CCJ2MH3N | D37: ='历史月度销量'!AZ6 | E37: ='历史月度销量'!BA6 | F37: ='历史月度销量'!BB6 | G37: ='历史月度销量'!BC6 | H37: ='历史月度销量'!BD6 | I37: ='历史月度销量'!BE6 | J37: ='历史月度销量'!BF6 | K37: ='历史月度销量'!BG6 | ... T37: ='历史月度销量'!BP6 | U37: =W37*0.87 | V37: {=_xlfn.XLOOKUP(C37,'26年实际销量'!A:A,'26年实际销量'!X:X)} | W37: 21889 | X37: =ROUND(I37/H37*T37,0) | Y37: =(U37-T37)/T37
A38: {=_xlfn.XLOOKUP(C38,'产品基础信息'!B:B,'产品基础信息'!C:C)} | B38: US | C38: B0D17P9F9S | D38: ='历史月度销量'!AZ7 | E38: ='历史月度销量'!BA7 | F38: ='历史月度销量'!BB7 | G38: ='历史月度销量'!BC7 | H38: ='历史月度销量'!BD7 | I38: ='历史月度销量'!BE7 | J38: ='历史月度销量'!BF7 | K38: ='历史月度销量'!BG7 | ... T38: ='历史月度销量'!BP7 | U38: =W38*0.87 | V38: {=_xlfn.XLOOKUP(C38,'26年实际销量'!A:A,'26年实际销量'!X:X)} | W38: 1390 | X38: =ROUND(I38/H38*T38,0) | Y38: =(U38-T38)/T38
A39: {=_xlfn.XLOOKUP(C39,'产品基础信息'!B:B,'产品基础信息'!C:C)} | B39: US | C39: B0D4PHQJYJ | D39: ='历史月度销量'!AZ8 | E39: ='历史月度销量'!BA8 | F39: ='历史月度销量'!BB8 | G39: ='历史月度销量'!BC8 | H39: ='历史月度销量'!BD8 | I39: ='历史月度销量'!BE8 | J39: ='历史月度销量'!BF8 | K39: ='历史月度销量'!BG8 | ... T39: ='历史月度销量'!BP8 | U39: =W39*0.87 | V39: {=_xlfn.XLOOKUP(C39,'26年实际销量'!A:A,'26年实际销量'!X:X)} | W39: 1897 | X39: =ROUND(I39/H39*T39,0) | Y39: =(U39-T39)/T39
A40: {=_xlfn.XLOOKUP(C40,'产品基础信息'!B:B,'产品基础信息'!C:C)} | B40: US | C40: B0FWJY4CCQ | D40: ='历史月度销量'!AZ9 | E40: ='历史月度销量'!BA9 | F40: ='历史月度销量'!BB9 | G40: ='历史月度销量'!BC9 | H40: ='历史月度销量'!BD9 | I40: ='历史月度销量'!BE9 | J40: ='历史月度销量'!BF9 | K40: ='历史月度销量'!BG9 | ... T40: ='历史月度销量'!BP9 | U40: =W40*0.87 | V40: {=_xlfn.XLOOKUP(C40,'26年实际销量'!A:A,'26年实际销量'!X:X)} | W40: 1599 | X40: =ROUND(I40/H40*T40,0) | Y40: =(U40-T40)/T40
A41: {=_xlfn.XLOOKUP(C41,'产品基础信息'!B:B,'产品基础信息'!C:C)} | B41: US | C41: B0DBPK9CTR | D41: ='历史月度销量'!AZ10 | E41: ='历史月度销量'!BA10 | F41: ='历史月度销量'!BB10 | G41: ='历史月度销量'!BC10 | H41: ='历史月度销量'!BD10 | I41: ='历史月度销量'!BE10 | J41: ='历史月度销量'!BF10 | K41: ='历史月度销量'!BG10 | ... T41: ='历史月度销量'!BP10 | U41: =W41*0.87 | V41: {=_xlfn.XLOOKUP(C41,'26年实际销量'!A:A,'26年实际销量'!X:X)} | W41: 1352 | X41: =ROUND(I41/H41*T41,0) | Y41: =(U41-T41)/T41
A42: {=_xlfn.XLOOKUP(C42,'产品基础信息'!B:B,'产品基础信息'!C:C)} | B42: US | C42: B0DBLYWHF4 | D42: ='历史月度销量'!AZ11 | E42: ='历史月度销量'!BA11 | F42: ='历史月度销量'!BB11 | G42: ='历史月度销量'!BC11 | H42: ='历史月度销量'!BD11 | I42: ='历史月度销量'!BE11 | J42: ='历史月度销量'!BF11 | K42: ='历史月度销量'!BG11 | ... T42: ='历史月度销量'!BP11 | U42: =X42 | V42: {=_xlfn.XLOOKUP(C42,'26年实际销量'!A:A,'26年实际销量'!X:X)} | W42: 2693 | X42: =ROUND(I42/H42*T42,0) | Y42: =(U42-T42)/T42
A43: {=_xlfn.XLOOKUP(C43,'产品基础信息'!B:B,'产品基础信息'!C:C)} | B43: CA | C43: B0CT5G5TVT | D43: ='历史月度销量'!AZ12 | E43: ='历史月度销量'!BA12 | F43: ='历史月度销量'!BB12 | G43: ='历史月度销量'!BC12 | H43: ='历史月度销量'!BD12 | I43: ='历史月度销量'!BE12 | J43: ='历史月度销量'!BF12 | K43: ='历史月度销量'!BG12 | ... T43: ='历史月度销量'!BP12 | U43: =X43 | V43: {=_xlfn.XLOOKUP(C43,'26年实际销量'!A:A,'26年实际销量'!X:X)} | W43: 2568 | X43: =ROUND(I43/H43*T43,0) | Y43: =(U43-T43)/T43
A44: {=_xlfn.XLOOKUP(C44,'产品基础信息'!B:B,'产品基础信息'!C:C)} | B44: CA | C44: B0D3J2Q1JM | D44: ='历史月度销量'!AZ13 | E44: ='历史月度销量'!BA13 | F44: ='历史月度销量'!BB13 | G44: ='历史月度销量'!BC13 | H44: ='历史月度销量'!BD13 | I44: ='历史月度销量'!BE13 | J44: ='历史月度销量'!BF13 | K44: ='历史月度销量'!BG13 | ... T44: ='历史月度销量'!BP13 | U44: =X44 | V44: {=_xlfn.XLOOKUP(C44,'26年实际销量'!A:A,'26年实际销量'!X:X)} | W44: 2120 | X44: =ROUND(I44/H44*T44,0) | Y44: =(X44-T44)/T44
A45: {=_xlfn.XLOOKUP(C45,'产品基础信息'!B:B,'产品基础信息'!C:C)} | B45: CA | C45: B0D3TS4TYR | D45: ='历史月度销量'!AZ14 | E45: ='历史月度销量'!BA14 | F45: ='历史月度销量'!BB14 | G45: ='历史月度销量'!BC14 | H45: ='历史月度销量'!BD14 | I45: ='历史月度销量'!BE14 | J45: ='历史月度销量'!BF14 | K45: ='历史月度销量'!BG14 | ... T45: ='历史月度销量'!BP14 | U45: =X45 | V45: {=_xlfn.XLOOKUP(C45,'26年实际销量'!A:A,'26年实际销量'!X:X)} | W45: 1199 | X45: =ROUND(I45/H45*T45,0) | Y45: =(X45-T45)/T45
A46: {=_xlfn.XLOOKUP(C46,'产品基础信息'!B:B,'产品基础信息'!C:C)} | B46: CA | C46: B0DRFTHNM8 | D46: ='历史月度销量'!AZ15 | E46: ='历史月度销量'!BA15 | F46: ='历史月度销量'!BB15 | G46: ='历史月度销量'!BC15 | H46: ='历史月度销量'!BD15 | I46: ='历史月度销量'!BE15 | J46: ='历史月度销量'!BF15 | K46: ='历史月度销量'!BG15 | ... T46: ='历史月度销量'!BP15 | U46: =X46 | V46: {=_xlfn.XLOOKUP(C46,'26年实际销量'!A:A,'26年实际销量'!X:X)} | W46: 758 | X46: =ROUND(I46/H46*T46,0) | Y46: =(X46-T46)/T46
...

Sheet 产品基础信息
A1: 站点 | B1: 父ASIN | C1: 父msku | D1: SPU | E1: 核心对标竞品 (ASIN) | F1: 备注
A2: US | B2: B0CSKDP26Z | C2: PDD25-A | E2: B0CC8M92B9
A3: US | B3: B0BSKX7ZHN | C3: PPDD05 | E3: B0C2YVV59F
A4: US | B4: B0B2PCVNYJ | C4: PPDD03-new diamond | E4: B091YMYV7Q
A5: US | B5: B0CCJ2MH3N | C5: PPD17 | E5: B09YCTD74F
A6: US | B6: B0D17P9F9S | C6: PPDD33 | D6: PD33、PPDD33 | E6: B0CMTKTYCQ
A7: US | B7: B0D4PHQJYJ | C7: PD52 | E7: B0CMTKTYCQ
A8: US | B8: B0FWJY4CCQ | C8: PD39-NEW | D8: PD39、PPDD39、PDM071 | E8: B0CMTKTYCQ
A9: US | B9: B0DBPK9CTR | C9: XD03 | E9: B0DP7BQ88V
A10: US | B10: B0DBLYWHF4 | C10: XD17 | E10: B0DBPNHHVP
A11: CA | B11: B0CT5G5TVT | C11: CPPDD03-NEW | E11: B0DFM4LVRV
A12: CA | B12: B0D3J2Q1JM | C12: NEWCPD17 | E12: B0BNDLPW1L
A13: CA | B13: B0D3TS4TYR | C13: CPD05-1 | E13: B0CLNRF9P3
A14: CA | B14: B0DRFTHNM8 | C14: CPDD25 | E14: B0BNDD4CR4

Sheet 历史月度销量
B1: 站点 | C1: 父ASIN | D1: 月度增长速率 | P1: 2026年 | V1: 月度销量占比 | AH1: 2026年 | AN1: 2024年 | AZ1: 2025年 | BL1: 2026年 | BY1: 2027年(大盘年度增幅) | CE1: 0.039223415 | CF1: 2027年(大盘月度增幅) | CL1: 2027年(自身修正占比)
D2: 1月 | E2: 2月 | F2: 3月 | G2: 4月 | H2: 5月 | I2: 6月 | J2: 7月 | K2: 8月 | L2: 9月 | M2: 10月 | N2: 11月 | O2: 12月 | P2: 1月 | Q2: 2月 | R2: 3月 | S2: 4月 | T2: 5月 | U2: 6月 | V2: 1月 | W2: 2月 | X2: 3月 | Y2: 4月 | Z2: 5月 | AA2: 6月 | AB2: 7月 | AC2: 8月 | AD2: 9月 | AE2: 10月 | AF2: 11月 | AG2: 12月 | AH2: 1月 | AI2: 2月 | AJ2: 3月 | AK2: 4月 | AL2: 5月 | AM2: 6月 | AN2: 1月 | AO2: 2月 | AP2: 3月 | AQ2: 4月 | AR2: 5月 | AS2: 6月 | AT2: 7月 | AU2: 8月 | AV2: 9月 | AW2: 10月 | AX2: 11月 | AY2: 12月 | AZ2: 1月 | BA2: 2月 | BB2: 3月 | BC2: 4月 | BD2: 5月 | BE2: 6月 | BF2: 7月 | BG2: 8月 | BH2: 9月 | BI2: 10月 | BJ2: 11月 | BK2: 12月 | BL2: 1月 | BM2: 2月 | BN2: 3月 | BO2: 4月 | BP2: 5月 | BQ2: 6月加权销量 | BR2: 7月 | BS2: 6月实际销量 | BT2: 25年合计 | BU2: 月均值 | BV2: 26年合计 | BX2: 月均值 | BY2: 1月 | BZ2: 2月 | CA2: 3月 | CB2: 4月 | CC2: 5月 | CD2: 6月 | CF2: 1月 | CG2: 2月 | CH2: 3月 | CI2: 4月 | CJ2: 5月 | CK2: 6月 | CL2: 1月 | CM2: 2月 | CN2: 3月 | CO2: 4月 | CP2: 5月 | CQ2: 6月
A3: {=_xlfn.XLOOKUP(C3,'产品基础信息'!B:B,'产品基础信息'!C:C)} | B3: ='产品基础信息'!A2 | C3: ='产品基础信息'!B2 | D3: 0 | E3: =IFERROR((BA3-AZ3)/AZ3,"-") | F3: =IFERROR((BB3-BA3)/BA3,"-") | G3: =IFERROR((BC3-BB3)/BB3,"-") | H3: =IFERROR((BD3-BC3)/BC3,"-") | I3: =IFERROR((BE3-BD3)/BD3,"-") | J3: =IFERROR((BF3-BE3)/BE3,"-") | K3: =IFERROR((BG3-BF3)/BF3,"-") | L3: =IFERROR((BH3-BG3)/BG3,"-") | ... U3: =IFERROR((BQ3-BP3)/BP3,"-") | V3: =AZ3/SUM($AZ3:$BE3) | W3: =BA3/SUM($AZ3:$BE3) | X3: =BB3/SUM($AZ3:$BE3) | Y3: =BC3/SUM($AZ3:$BE3) | Z3: =BD3/SUM($AZ3:$BE3) | AA3: =BE3/SUM($AZ3:$BE3) | AH3: =BL3/SUM($BL3:$BQ3) | AI3: =BM3/SUM($BL3:$BQ3) | AJ3: =BN3/SUM($BL3:$BQ3) | AK3: =BO3/SUM($BL3:$BQ3) | AL3: =BP3/SUM($BL3:$BQ3) | AM3: =BQ3/SUM($BL3:$BQ3) | AZ3: =SUMIFS('25年实际销量'!M:M,'25年实际销量'!$A:$A,$C:$C) | BA3: =SUMIFS('25年实际销量'!N:N,'25年实际销量'!$A:$A,$C:$C) | BB3: =SUMIFS('25年实际销量'!O:O,'25年实际销量'!$A:$A,$C:$C) | BC3: =SUMIFS('25年实际销量'!P:P,'25年实际销量'!$A:$A,$C:$C) | BD3: =SUMIFS('25年实际销量'!Q:Q,'25年实际销量'!$A:$A,$C:$C) | BE3: =SUMIFS('25年实际销量'!R:R,'25年实际销量'!$A:$A,$C:$C) | BF3: =SUMIFS('25年实际销量'!S:S,'25年实际销量'!$A:$A,$C:$C) | BG3: =SUMIFS('25年实际销量'!T:T,'25年实际销量'!$A:$A,$C:$C) | BH3: =SUMIFS('25年实际销量'!U:U,'25年实际销量'!$A:$A,$C:$C) | BI3: =SUMIFS('25年实际销量'!V:V,'25年实际销量'!$A:$A,$C:$C) | BJ3: =SUMIFS('25年实际销量'!W:W,'25年实际销量'!$A:$A,$C:$C) | BK3: =SUMIFS('25年实际销量'!X:X,'25年实际销量'!$A:$A,$C:$C) | BL3: =SUMIFS('26年实际销量'!R:R,'26年实际销量'!$A:$A,$C:$C) | BM3: =SUMIFS('26年实际销量'!S:S,'26年实际销量'!$A:$A,$C:$C) | BN3: =SUMIFS('26年实际销量'!T:T,'26年实际销量'!$A:$A,$C:$C) | BO3: =SUMIFS('26年实际销量'!U:U,'26年实际销量'!$A:$A,$C:$C) | BP3: =SUMIFS('26年实际销量'!V:V,'26年实际销量'!$A:$A,$C:$C) | BQ3: =BS3*0.6+BR3*0.4 | BR3: {=_xlfn.XLOOKUP(C:C,'26年实际销量'!A:A,'26年实际销量'!X:X)} | BS3: 7492 | BT3: =SUM(AZ3:BK3) | BU3: =IF(BT3=0,0,BT3/12) | BV3: =SUM(BL3:BQ3) | BW3: {=_xlfn.XLOOKUP(C:C,'基础销量预测-计划端'!C:C,'基础销量预测-计划端'!AG:AG)} | BX3: =IF(BV3=0,0,BV3/6) | BY3: =ROUND(BL3*($CE$1+1),0) | BZ3: =ROUND(BM3*($CE$1+1),0) | CA3: =ROUND(BN3*($CE$1+1),0) | CB3: =ROUND(BO3*($CE$1+1),0) | CC3: =ROUND(BP3*($CE$1+1),0) | CD3: =ROUND(BQ3*($CE$1+1),0) | CL3: =(AH3*0.7+V3*0.3) | CM3: =(AI3*0.7+W3*0.3) | CN3: =(AJ3*0.7+X3*0.3) | CO3: =(AK3*0.7+Y3*0.3) | CP3: =(AL3*0.7+Z3*0.3) | CQ3: =(AM3*0.7+AA3*0.3)
A4: {=_xlfn.XLOOKUP(C4,'产品基础信息'!B:B,'产品基础信息'!C:C)} | B4: ='产品基础信息'!A3 | C4: ='产品基础信息'!B3 | D4: 0 | E4: =(BA4-AZ4)/AZ4 | F4: =(BB4-BA4)/BA4 | G4: =(BC4-BB4)/BB4 | H4: =(BD4-BC4)/BC4 | I4: =(BE4-BD4)/BD4 | J4: =(BF4-BE4)/BE4 | K4: =(BG4-BF4)/BF4 | L4: =(BH4-BG4)/BG4 | ... U4: =(BQ4-BP4)/BP4 | V4: =AZ4/SUM($AZ4:$BE4) | W4: =BA4/SUM($AZ4:$BE4) | X4: =BB4/SUM($AZ4:$BE4) | Y4: =BC4/SUM($AZ4:$BE4) | Z4: =BD4/SUM($AZ4:$BE4) | AA4: =BE4/SUM($AZ4:$BE4) | AH4: =BL4/SUM($BL4:$BQ4) | AI4: =BM4/SUM($BL4:$BQ4) | AJ4: =BN4/SUM($BL4:$BQ4) | AK4: =BO4/SUM($BL4:$BQ4) | AL4: =BP4/SUM($BL4:$BQ4) | AM4: =BQ4/SUM($BL4:$BQ4) | AZ4: =SUMIFS('25年实际销量'!M:M,'25年实际销量'!$A:$A,$C:$C) | BA4: =SUMIFS('25年实际销量'!N:N,'25年实际销量'!$A:$A,$C:$C) | BB4: =SUMIFS('25年实际销量'!O:O,'25年实际销量'!$A:$A,$C:$C) | BC4: =SUMIFS('25年实际销量'!P:P,'25年实际销量'!$A:$A,$C:$C) | BD4: =SUMIFS('25年实际销量'!Q:Q,'25年实际销量'!$A:$A,$C:$C) | BE4: =SUMIFS('25年实际销量'!R:R,'25年实际销量'!$A:$A,$C:$C) | BF4: =SUMIFS('25年实际销量'!S:S,'25年实际销量'!$A:$A,$C:$C) | BG4: =SUMIFS('25年实际销量'!T:T,'25年实际销量'!$A:$A,$C:$C) | BH4: =SUMIFS('25年实际销量'!U:U,'25年实际销量'!$A:$A,$C:$C) | BI4: =SUMIFS('25年实际销量'!V:V,'25年实际销量'!$A:$A,$C:$C) | BJ4: =SUMIFS('25年实际销量'!W:W,'25年实际销量'!$A:$A,$C:$C) | BK4: =SUMIFS('25年实际销量'!X:X,'25年实际销量'!$A:$A,$C:$C) | BL4: =SUMIFS('26年实际销量'!R:R,'26年实际销量'!$A:$A,$C:$C) | BM4: =SUMIFS('26年实际销量'!S:S,'26年实际销量'!$A:$A,$C:$C) | BN4: =SUMIFS('26年实际销量'!T:T,'26年实际销量'!$A:$A,$C:$C) | BO4: =SUMIFS('26年实际销量'!U:U,'26年实际销量'!$A:$A,$C:$C) | BP4: =SUMIFS('26年实际销量'!V:V,'26年实际销量'!$A:$A,$C:$C) | BQ4: =BS4*0.6+BR4*0.4 | BR4: {=_xlfn.XLOOKUP(C:C,'26年实际销量'!A:A,'26年实际销量'!X:X)} | BS4: 9323 | BT4: =SUM(AZ4:BK4) | BU4: =IF(BT4=0,0,BT4/12) | BV4: =SUM(BL4:BQ4) | BW4: {=_xlfn.XLOOKUP(C:C,'基础销量预测-计划端'!C:C,'基础销量预测-计划端'!AG:AG)} | BX4: =IF(BV4=0,0,BV4/6) | BY4: =ROUND(BL4*($CE$1+1),0) | BZ4: =ROUND(BM4*($CE$1+1),0) | CA4: =ROUND(BN4*($CE$1+1),0) | CB4: =ROUND(BO4*($CE$1+1),0) | CC4: =ROUND(BP4*($CE$1+1),0) | CD4: =ROUND(BQ4*($CE$1+1),0) | CL4: =(AH4*0.7+V4*0.3) | CM4: =(AI4*0.7+W4*0.3) | CN4: =(AJ4*0.7+X4*0.3) | CO4: =(AK4*0.7+Y4*0.3) | CP4: =(AL4*0.7+Z4*0.3) | CQ4: =(AM4*0.7+AA4*0.3)
A5: {=_xlfn.XLOOKUP(C5,'产品基础信息'!B:B,'产品基础信息'!C:C)} | B5: ='产品基础信息'!A4 | C5: ='产品基础信息'!B4 | D5: 0 | E5: =(BA5-AZ5)/AZ5 | F5: =(BB5-BA5)/BA5 | G5: =(BC5-BB5)/BB5 | H5: =(BD5-BC5)/BC5 | I5: =(BE5-BD5)/BD5 | J5: =(BF5-BE5)/BE5 | K5: =(BG5-BF5)/BF5 | L5: =(BH5-BG5)/BG5 | ... U5: =(BQ5-BP5)/BP5 | V5: =AZ5/SUM($AZ5:$BE5) | W5: =BA5/SUM($AZ5:$BE5) | X5: =BB5/SUM($AZ5:$BE5) | Y5: =BC5/SUM($AZ5:$BE5) | Z5: =BD5/SUM($AZ5:$BE5) | AA5: =BE5/SUM($AZ5:$BE5) | AH5: =BL5/SUM($BL5:$BQ5) | AI5: =BM5/SUM($BL5:$BQ5) | AJ5: =BN5/SUM($BL5:$BQ5) | AK5: =BO5/SUM($BL5:$BQ5) | AL5: =BP5/SUM($BL5:$BQ5) | AM5: =BQ5/SUM($BL5:$BQ5) | AZ5: =SUMIFS('25年实际销量'!M:M,'25年实际销量'!$A:$A,$C:$C) | BA5: =SUMIFS('25年实际销量'!N:N,'25年实际销量'!$A:$A,$C:$C) | BB5: =SUMIFS('25年实际销量'!O:O,'25年实际销量'!$A:$A,$C:$C) | BC5: =SUMIFS('25年实际销量'!P:P,'25年实际销量'!$A:$A,$C:$C) | BD5: =SUMIFS('25年实际销量'!Q:Q,'25年实际销量'!$A:$A,$C:$C) | BE5: =SUMIFS('25年实际销量'!R:R,'25年实际销量'!$A:$A,$C:$C) | BF5: =SUMIFS('25年实际销量'!S:S,'25年实际销量'!$A:$A,$C:$C) | BG5: =SUMIFS('25年实际销量'!T:T,'25年实际销量'!$A:$A,$C:$C) | BH5: =SUMIFS('25年实际销量'!U:U,'25年实际销量'!$A:$A,$C:$C) | BI5: =SUMIFS('25年实际销量'!V:V,'25年实际销量'!$A:$A,$C:$C) | BJ5: =SUMIFS('25年实际销量'!W:W,'25年实际销量'!$A:$A,$C:$C) | BK5: =SUMIFS('25年实际销量'!X:X,'25年实际销量'!$A:$A,$C:$C) | BL5: =SUMIFS('26年实际销量'!R:R,'26年实际销量'!$A:$A,$C:$C) | BM5: =SUMIFS('26年实际销量'!S:S,'26年实际销量'!$A:$A,$C:$C) | BN5: =SUMIFS('26年实际销量'!T:T,'26年实际销量'!$A:$A,$C:$C) | BO5: =SUMIFS('26年实际销量'!U:U,'26年实际销量'!$A:$A,$C:$C) | BP5: =SUMIFS('26年实际销量'!V:V,'26年实际销量'!$A:$A,$C:$C) | BQ5: =BS5*0.6+BR5*0.4 | BR5: {=_xlfn.XLOOKUP(C:C,'26年实际销量'!A:A,'26年实际销量'!X:X)} | BS5: 19707 | BT5: =SUM(AZ5:BK5) | BU5: =IF(BT5=0,0,BT5/12) | BV5: =SUM(BL5:BQ5) | BW5: {=_xlfn.XLOOKUP(C:C,'基础销量预测-计划端'!C:C,'基础销量预测-计划端'!AG:AG)} | BX5: =IF(BV5=0,0,BV5/6) | BY5: =ROUND(BL5*($CE$1+1),0) | BZ5: =ROUND(BM5*($CE$1+1),0) | CA5: =ROUND(BN5*($CE$1+1),0) | CB5: =ROUND(BO5*($CE$1+1),0) | CC5: =ROUND(BP5*($CE$1+1),0) | CD5: =ROUND(BQ5*($CE$1+1),0) | CL5: =(AH5*0.7+V5*0.3) | CM5: =(AI5*0.7+W5*0.3) | CN5: =(AJ5*0.7+X5*0.3) | CO5: =(AK5*0.7+Y5*0.3) | CP5: =(AL5*0.7+Z5*0.3) | CQ5: =(AM5*0.7+AA5*0.3)
A6: {=_xlfn.XLOOKUP(C6,'产品基础信息'!B:B,'产品基础信息'!C:C)} | B6: ='产品基础信息'!A5 | C6: ='产品基础信息'!B5 | D6: 0 | E6: =(BA6-AZ6)/AZ6 | F6: =(BB6-BA6)/BA6 | G6: =(BC6-BB6)/BB6 | H6: =(BD6-BC6)/BC6 | I6: =(BE6-BD6)/BD6 | J6: =(BF6-BE6)/BE6 | K6: =(BG6-BF6)/BF6 | L6: =(BH6-BG6)/BG6 | ... U6: =(BQ6-BP6)/BP6 | V6: =AZ6/SUM($AZ6:$BE6) | W6: =BA6/SUM($AZ6:$BE6) | X6: =BB6/SUM($AZ6:$BE6) | Y6: =BC6/SUM($AZ6:$BE6) | Z6: =BD6/SUM($AZ6:$BE6) | AA6: =BE6/SUM($AZ6:$BE6) | AH6: =BL6/SUM($BL6:$BQ6) | AI6: =BM6/SUM($BL6:$BQ6) | AJ6: =BN6/SUM($BL6:$BQ6) | AK6: =BO6/SUM($BL6:$BQ6) | AL6: =BP6/SUM($BL6:$BQ6) | AM6: =BQ6/SUM($BL6:$BQ6) | AZ6: =SUMIFS('25年实际销量'!M:M,'25年实际销量'!$A:$A,$C:$C) | BA6: =SUMIFS('25年实际销量'!N:N,'25年实际销量'!$A:$A,$C:$C) | BB6: =SUMIFS('25年实际销量'!O:O,'25年实际销量'!$A:$A,$C:$C) | BC6: =SUMIFS('25年实际销量'!P:P,'25年实际销量'!$A:$A,$C:$C) | BD6: =SUMIFS('25年实际销量'!Q:Q,'25年实际销量'!$A:$A,$C:$C) | BE6: =SUMIFS('25年实际销量'!R:R,'25年实际销量'!$A:$A,$C:$C) | BF6: =SUMIFS('25年实际销量'!S:S,'25年实际销量'!$A:$A,$C:$C) | BG6: =SUMIFS('25年实际销量'!T:T,'25年实际销量'!$A:$A,$C:$C) | BH6: =SUMIFS('25年实际销量'!U:U,'25年实际销量'!$A:$A,$C:$C) | BI6: =SUMIFS('25年实际销量'!V:V,'25年实际销量'!$A:$A,$C:$C) | BJ6: =SUMIFS('25年实际销量'!W:W,'25年实际销量'!$A:$A,$C:$C) | BK6: =SUMIFS('25年实际销量'!X:X,'25年实际销量'!$A:$A,$C:$C) | BL6: =SUMIFS('26年实际销量'!R:R,'26年实际销量'!$A:$A,$C:$C) | BM6: =SUMIFS('26年实际销量'!S:S,'26年实际销量'!$A:$A,$C:$C) | BN6: =SUMIFS('26年实际销量'!T:T,'26年实际销量'!$A:$A,$C:$C) | BO6: =SUMIFS('26年实际销量'!U:U,'26年实际销量'!$A:$A,$C:$C) | BP6: =SUMIFS('26年实际销量'!V:V,'26年实际销量'!$A:$A,$C:$C) | BQ6: =BS6*0.6+BR6*0.4 | BR6: {=_xlfn.XLOOKUP(C:C,'26年实际销量'!A:A,'26年实际销量'!X:X)} | BS6: 21889 | BT6: =SUM(AZ6:BK6) | BU6: =IF(BT6=0,0,BT6/12) | BV6: =SUM(BL6:BQ6) | BW6: {=_xlfn.XLOOKUP(C:C,'基础销量预测-计划端'!C:C,'基础销量预测-计划端'!AG:AG)} | BX6: =IF(BV6=0,0,BV6/6) | BY6: =ROUND(BL6*($CE$1+1),0) | BZ6: =ROUND(BM6*($CE$1+1),0) | CA6: =ROUND(BN6*($CE$1+1),0) | CB6: =ROUND(BO6*($CE$1+1),0) | CC6: =ROUND(BP6*($CE$1+1),0) | CD6: =ROUND(BQ6*($CE$1+1),0) | CL6: =(AH6*0.7+V6*0.3) | CM6: =(AI6*0.7+W6*0.3) | CN6: =(AJ6*0.7+X6*0.3) | CO6: =(AK6*0.7+Y6*0.3) | CP6: =(AL6*0.7+Z6*0.3) | CQ6: =(AM6*0.7+AA6*0.3)
A7: {=_xlfn.XLOOKUP(C7,'产品基础信息'!B:B,'产品基础信息'!C:C)} | B7: ='产品基础信息'!A6 | C7: ='产品基础信息'!B6 | D7: =AZ7/SUM($AZ7:$BK7) | E7: =(BA7-AZ7)/AZ7 | F7: =(BB7-BA7)/BA7 | G7: =(BC7-BB7)/BB7 | H7: =(BD7-BC7)/BC7 | I7: =(BE7-BD7)/BD7 | J7: =(BF7-BE7)/BE7 | K7: =(BG7-BF7)/BF7 | L7: =(BH7-BG7)/BG7 | ... O7: =(BK7-BJ7)/BJ7 | P7: =BL7/SUM($BL7:$BQ7) | Q7: =BM7/SUM($BL7:$BQ7) | R7: =BN7/SUM($BL7:$BQ7) | S7: =BO7/SUM($BL7:$BQ7) | T7: =BP7/SUM($BL7:$BQ7) | U7: =BQ7/SUM($BL7:$BQ7) | V7: =AZ7/SUM($AZ7:$BE7) | W7: =BA7/SUM($AZ7:$BE7) | X7: =BB7/SUM($AZ7:$BE7) | Y7: =BC7/SUM($AZ7:$BE7) | Z7: =BD7/SUM($AZ7:$BE7) | AA7: =BE7/SUM($AZ7:$BE7) | AH7: =BL7/SUM($BL7:$BQ7) | AI7: =BM7/SUM($BL7:$BQ7) | AJ7: =BN7/SUM($BL7:$BQ7) | AK7: =BO7/SUM($BL7:$BQ7) | AL7: =BP7/SUM($BL7:$BQ7) | AM7: =BQ7/SUM($BL7:$BQ7) | AZ7: =SUMIFS('25年实际销量'!M:M,'25年实际销量'!$A:$A,$C:$C) | BA7: =SUMIFS('25年实际销量'!N:N,'25年实际销量'!$A:$A,$C:$C) | BB7: =SUMIFS('25年实际销量'!O:O,'25年实际销量'!$A:$A,$C:$C) | BC7: =SUMIFS('25年实际销量'!P:P,'25年实际销量'!$A:$A,$C:$C) | BD7: =SUMIFS('25年实际销量'!Q:Q,'25年实际销量'!$A:$A,$C:$C) | BE7: =SUMIFS('25年实际销量'!R:R,'25年实际销量'!$A:$A,$C:$C) | BF7: =SUMIFS('25年实际销量'!S:S,'25年实际销量'!$A:$A,$C:$C) | BG7: =SUMIFS('25年实际销量'!T:T,'25年实际销量'!$A:$A,$C:$C) | BH7: =SUMIFS('25年实际销量'!U:U,'25年实际销量'!$A:$A,$C:$C) | BI7: =SUMIFS('25年实际销量'!V:V,'25年实际销量'!$A:$A,$C:$C) | BJ7: =SUMIFS('25年实际销量'!W:W,'25年实际销量'!$A:$A,$C:$C) | BK7: =SUMIFS('25年实际销量'!X:X,'25年实际销量'!$A:$A,$C:$C) | BL7: =SUMIFS('26年实际销量'!R:R,'26年实际销量'!$A:$A,$C:$C) | BM7: =SUMIFS('26年实际销量'!S:S,'26年实际销量'!$A:$A,$C:$C) | BN7: =SUMIFS('26年实际销量'!T:T,'26年实际销量'!$A:$A,$C:$C) | BO7: =SUMIFS('26年实际销量'!U:U,'26年实际销量'!$A:$A,$C:$C) | BP7: =SUMIFS('26年实际销量'!V:V,'26年实际销量'!$A:$A,$C:$C) | BQ7: =BS7*0.6+BR7*0.4 | BR7: {=_xlfn.XLOOKUP(C:C,'26年实际销量'!A:A,'26年实际销量'!X:X)} | BS7: 1390 | BT7: =SUM(AZ7:BK7) | BU7: =IF(BT7=0,0,BT7/12) | BV7: =SUM(BL7:BQ7) | BW7: {=_xlfn.XLOOKUP(C:C,'基础销量预测-计划端'!C:C,'基础销量预测-计划端'!AG:AG)} | BX7: =IF(BV7=0,0,BV7/6) | BY7: =ROUND(BL7*($CE$1+1),0) | BZ7: =ROUND(BM7*($CE$1+1),0) | CA7: =ROUND(BN7*($CE$1+1),0) | CB7: =ROUND(BO7*($CE$1+1),0) | CC7: =ROUND(BP7*($CE$1+1),0) | CD7: =ROUND(BQ7*($CE$1+1),0) | CL7: =(AH7*0.7+V7*0.3) | CM7: =(AI7*0.7+W7*0.3) | CN7: =(AJ7*0.7+X7*0.3) | CO7: =(AK7*0.7+Y7*0.3) | CP7: =(AL7*0.7+Z7*0.3) | CQ7: =(AM7*0.7+AA7*0.3)
A8: {=_xlfn.XLOOKUP(C8,'产品基础信息'!B:B,'产品基础信息'!C:C)} | B8: ='产品基础信息'!A7 | C8: ='产品基础信息'!B7 | D8: =AZ8/SUM($AZ8:$BK8) | E8: =(BA8-AZ8)/AZ8 | F8: =(BB8-BA8)/BA8 | G8: =(BC8-BB8)/BB8 | H8: =(BD8-BC8)/BC8 | I8: =(BE8-BD8)/BD8 | J8: =(BF8-BE8)/BE8 | K8: =(BG8-BF8)/BF8 | L8: =(BH8-BG8)/BG8 | ... O8: =(BK8-BJ8)/BJ8 | P8: =BL8/SUM($BL8:$BQ8) | Q8: =BM8/SUM($BL8:$BQ8) | R8: =BN8/SUM($BL8:$BQ8) | S8: =BO8/SUM($BL8:$BQ8) | T8: =BP8/SUM($BL8:$BQ8) | U8: =BQ8/SUM($BL8:$BQ8) | V8: =AZ8/SUM($AZ8:$BE8) | W8: =BA8/SUM($AZ8:$BE8) | X8: =BB8/SUM($AZ8:$BE8) | Y8: =BC8/SUM($AZ8:$BE8) | Z8: =BD8/SUM($AZ8:$BE8) | AA8: =BE8/SUM($AZ8:$BE8) | AH8: =BL8/SUM($BL8:$BQ8) | AI8: =BM8/SUM($BL8:$BQ8) | AJ8: =BN8/SUM($BL8:$BQ8) | AK8: =BO8/SUM($BL8:$BQ8) | AL8: =BP8/SUM($BL8:$BQ8) | AM8: =BQ8/SUM($BL8:$BQ8) | AZ8: =SUMIFS('25年实际销量'!M:M,'25年实际销量'!$A:$A,$C:$C) | BA8: =SUMIFS('25年实际销量'!N:N,'25年实际销量'!$A:$A,$C:$C) | BB8: =SUMIFS('25年实际销量'!O:O,'25年实际销量'!$A:$A,$C:$C) | BC8: =SUMIFS('25年实际销量'!P:P,'25年实际销量'!$A:$A,$C:$C) | BD8: =SUMIFS('25年实际销量'!Q:Q,'25年实际销量'!$A:$A,$C:$C) | BE8: =SUMIFS('25年实际销量'!R:R,'25年实际销量'!$A:$A,$C:$C) | BF8: =SUMIFS('25年实际销量'!S:S,'25年实际销量'!$A:$A,$C:$C) | BG8: =SUMIFS('25年实际销量'!T:T,'25年实际销量'!$A:$A,$C:$C) | BH8: =SUMIFS('25年实际销量'!U:U,'25年实际销量'!$A:$A,$C:$C) | BI8: =SUMIFS('25年实际销量'!V:V,'25年实际销量'!$A:$A,$C:$C) | BJ8: =SUMIFS('25年实际销量'!W:W,'25年实际销量'!$A:$A,$C:$C) | BK8: =SUMIFS('25年实际销量'!X:X,'25年实际销量'!$A:$A,$C:$C) | BL8: =SUMIFS('26年实际销量'!R:R,'26年实际销量'!$A:$A,$C:$C) | BM8: =SUMIFS('26年实际销量'!S:S,'26年实际销量'!$A:$A,$C:$C) | BN8: =SUMIFS('26年实际销量'!T:T,'26年实际销量'!$A:$A,$C:$C) | BO8: =SUMIFS('26年实际销量'!U:U,'26年实际销量'!$A:$A,$C:$C) | BP8: =SUMIFS('26年实际销量'!V:V,'26年实际销量'!$A:$A,$C:$C) | BQ8: =BS8*0.6+BR8*0.4 | BR8: {=_xlfn.XLOOKUP(C:C,'26年实际销量'!A:A,'26年实际销量'!X:X)} | BS8: 1897 | BT8: =SUM(AZ8:BK8) | BU8: =IF(BT8=0,0,BT8/12) | BV8: =SUM(BL8:BQ8) | BW8: {=_xlfn.XLOOKUP(C:C,'基础销量预测-计划端'!C:C,'基础销量预测-计划端'!AG:AG)} | BX8: =IF(BV8=0,0,BV8/6) | BY8: =ROUND(BL8*($CE$1+1),0) | BZ8: =ROUND(BM8*($CE$1+1),0) | CA8: =ROUND(BN8*($CE$1+1),0) | CB8: =ROUND(BO8*($CE$1+1),0) | CC8: =ROUND(BP8*($CE$1+1),0) | CD8: =ROUND(BQ8*($CE$1+1),0) | CL8: =(AH8*0.7+V8*0.3) | CM8: =(AI8*0.7+W8*0.3) | CN8: =(AJ8*0.7+X8*0.3) | CO8: =(AK8*0.7+Y8*0.3) | CP8: =(AL8*0.7+Z8*0.3) | CQ8: =(AM8*0.7+AA8*0.3)
A9: {=_xlfn.XLOOKUP(C9,'产品基础信息'!B:B,'产品基础信息'!C:C)} | B9: ='产品基础信息'!A8 | C9: ='产品基础信息'!B8 | D9: 0 | E9: =(BA9-AZ9)/AZ9 | F9: =(BB9-BA9)/BA9 | G9: =(BC9-BB9)/BB9 | H9: =(BD9-BC9)/BC9 | I9: =(BE9-BD9)/BD9 | J9: =(BF9-BE9)/BE9 | K9: =(BG9-BF9)/BF9 | L9: =(BH9-BG9)/BG9 | ... O9: =(BK9-BJ9)/BJ9 | P9: 0 | Q9: 0 | R9: 0 | S9: =(BO9-BN9)/BN9 | T9: =(BP9-BO9)/BO9 | U9: =(BQ9-BP9)/BP9 | V9: 0 | W9: 0 | X9: 0 | Y9: 0 | Z9: 0 | AA9: 0 | AH9: =BL9/SUM($BL9:$BQ9) | AI9: =BM9/SUM($BL9:$BQ9) | AJ9: =BN9/SUM($BL9:$BQ9) | AK9: =BO9/SUM($BL9:$BQ9) | AL9: =BP9/SUM($BL9:$BQ9) | AM9: =BQ9/SUM($BL9:$BQ9) | AZ9: =SUMIFS('25年实际销量'!M:M,'25年实际销量'!$A:$A,$C:$C) | BA9: =SUMIFS('25年实际销量'!N:N,'25年实际销量'!$A:$A,$C:$C) | BB9: =SUMIFS('25年实际销量'!O:O,'25年实际销量'!$A:$A,$C:$C) | BC9: =SUMIFS('25年实际销量'!P:P,'25年实际销量'!$A:$A,$C:$C) | BD9: =SUMIFS('25年实际销量'!Q:Q,'25年实际销量'!$A:$A,$C:$C) | BE9: =SUMIFS('25年实际销量'!R:R,'25年实际销量'!$A:$A,$C:$C) | BF9: =SUMIFS('25年实际销量'!S:S,'25年实际销量'!$A:$A,$C:$C) | BG9: =SUMIFS('25年实际销量'!T:T,'25年实际销量'!$A:$A,$C:$C) | BH9: =SUMIFS('25年实际销量'!U:U,'25年实际销量'!$A:$A,$C:$C) | BI9: =SUMIFS('25年实际销量'!V:V,'25年实际销量'!$A:$A,$C:$C) | BJ9: =SUMIFS('25年实际销量'!W:W,'25年实际销量'!$A:$A,$C:$C) | BK9: =SUMIFS('25年实际销量'!X:X,'25年实际销量'!$A:$A,$C:$C) | BL9: =SUMIFS('26年实际销量'!R:R,'26年实际销量'!$A:$A,$C:$C) | BM9: =SUMIFS('26年实际销量'!S:S,'26年实际销量'!$A:$A,$C:$C) | BN9: =SUMIFS('26年实际销量'!T:T,'26年实际销量'!$A:$A,$C:$C) | BO9: =SUMIFS('26年实际销量'!U:U,'26年实际销量'!$A:$A,$C:$C) | BP9: =SUMIFS('26年实际销量'!V:V,'26年实际销量'!$A:$A,$C:$C) | BQ9: =BS9*0.6+BR9*0.4 | BR9: {=_xlfn.XLOOKUP(C:C,'26年实际销量'!A:A,'26年实际销量'!X:X)} | BS9: 1599 | BT9: =SUM(AZ9:BK9) | BU9: =IF(BT9=0,0,BT9/12) | BV9: =SUM(BL9:BQ9) | BW9: {=_xlfn.XLOOKUP(C:C,'基础销量预测-计划端'!C:C,'基础销量预测-计划端'!AG:AG)} | BX9: =IF(BV9=0,0,BV9/6) | BY9: =ROUND(BL9*($CE$1+1),0) | BZ9: =ROUND(BM9*($CE$1+1),0) | CA9: =ROUND(BN9*($CE$1+1),0) | CB9: =ROUND(BO9*($CE$1+1),0) | CC9: =ROUND(BP9*($CE$1+1),0) | CD9: =ROUND(BQ9*($CE$1+1),0) | CL9: =(AH9*0.7+V9*0.3) | CM9: =(AI9*0.7+W9*0.3) | CN9: =(AJ9*0.7+X9*0.3) | CO9: =(AK9*0.7+Y9*0.3) | CP9: =(AL9*0.7+Z9*0.3) | CQ9: =(AM9*0.7+AA9*0.3)
A10: {=_xlfn.XLOOKUP(C10,'产品基础信息'!B:B,'产品基础信息'!C:C)} | B10: ='产品基础信息'!A9 | C10: ='产品基础信息'!B9 | D10: 0 | E10: =(BA10-AZ10)/AZ10 | F10: =(BB10-BA10)/BA10 | G10: =(BC10-BB10)/BB10 | H10: =(BD10-BC10)/BC10 | I10: =(BE10-BD10)/BD10 | J10: =(BF10-BE10)/BE10 | K10: =(BG10-BF10)/BF10 | L10: =(BH10-BG10)/BG10 | ... O10: =(BK10-BJ10)/BJ10 | P10: 0 | Q10: =(BM10-BL10)/BL10 | R10: =(BN10-BM10)/BM10 | S10: =(BO10-BN10)/BN10 | T10: =(BP10-BO10)/BO10 | U10: =(BQ10-BP10)/BP10 | V10: 0 | W10: 0 | X10: 0 | Y10: 0 | Z10: 0 | AA10: 0 | AH10: =BL10/SUM($BL10:$BQ10) | AI10: =BM10/SUM($BL10:$BQ10) | AJ10: =BN10/SUM($BL10:$BQ10) | AK10: =BO10/SUM($BL10:$BQ10) | AL10: =BP10/SUM($BL10:$BQ10) | AM10: =BQ10/SUM($BL10:$BQ10) | AZ10: =SUMIFS('25年实际销量'!M:M,'25年实际销量'!$A:$A,$C:$C) | BA10: =SUMIFS('25年实际销量'!N:N,'25年实际销量'!$A:$A,$C:$C) | BB10: =SUMIFS('25年实际销量'!O:O,'25年实际销量'!$A:$A,$C:$C) | BC10: =SUMIFS('25年实际销量'!P:P,'25年实际销量'!$A:$A,$C:$C) | BD10: =SUMIFS('25年实际销量'!Q:Q,'25年实际销量'!$A:$A,$C:$C) | BE10: =SUMIFS('25年实际销量'!R:R,'25年实际销量'!$A:$A,$C:$C) | BF10: =SUMIFS('25年实际销量'!S:S,'25年实际销量'!$A:$A,$C:$C) | BG10: =SUMIFS('25年实际销量'!T:T,'25年实际销量'!$A:$A,$C:$C) | BH10: =SUMIFS('25年实际销量'!U:U,'25年实际销量'!$A:$A,$C:$C) | BI10: =SUMIFS('25年实际销量'!V:V,'25年实际销量'!$A:$A,$C:$C) | BJ10: =SUMIFS('25年实际销量'!W:W,'25年实际销量'!$A:$A,$C:$C) | BK10: =SUMIFS('25年实际销量'!X:X,'25年实际销量'!$A:$A,$C:$C) | BL10: =SUMIFS('26年实际销量'!R:R,'26年实际销量'!$A:$A,$C:$C) | BM10: =SUMIFS('26年实际销量'!S:S,'26年实际销量'!$A:$A,$C:$C) | BN10: =SUMIFS('26年实际销量'!T:T,'26年实际销量'!$A:$A,$C:$C) | BO10: =SUMIFS('26年实际销量'!U:U,'26年实际销量'!$A:$A,$C:$C) | BP10: =SUMIFS('26年实际销量'!V:V,'26年实际销量'!$A:$A,$C:$C) | BQ10: =BS10*0.6+BR10*0.4 | BR10: {=_xlfn.XLOOKUP(C:C,'26年实际销量'!A:A,'26年实际销量'!X:X)} | BS10: 1352 | BT10: =SUM(AZ10:BK10) | BU10: =IF(BT10=0,0,BT10/12) | BV10: =SUM(BL10:BQ10) | BW10: {=_xlfn.XLOOKUP(C:C,'基础销量预测-计划端'!C:C,'基础销量预测-计划端'!AG:AG)} | BX10: =IF(BV10=0,0,BV10/6) | BY10: =ROUND(BL10*($CE$1+1),0) | BZ10: =ROUND(BM10*($CE$1+1),0) | CA10: =ROUND(BN10*($CE$1+1),0) | CB10: =ROUND(BO10*($CE$1+1),0) | CC10: =ROUND(BP10*($CE$1+1),0) | CD10: =ROUND(BQ10*($CE$1+1),0) | CL10: =(AH10*0.7+V10*0.3) | CM10: =(AI10*0.7+W10*0.3) | CN10: =(AJ10*0.7+X10*0.3) | CO10: =(AK10*0.7+Y10*0.3) | CP10: =(AL10*0.7+Z10*0.3) | CQ10: =(AM10*0.7+AA10*0.3)
A11: {=_xlfn.XLOOKUP(C11,'产品基础信息'!B:B,'产品基础信息'!C:C)} | B11: ='产品基础信息'!A10 | C11: ='产品基础信息'!B10 | D11: 0 | E11: =(BA11-AZ11)/AZ11 | F11: =(BB11-BA11)/BA11 | G11: =(BC11-BB11)/BB11 | H11: =(BD11-BC11)/BC11 | I11: =(BE11-BD11)/BD11 | J11: =(BF11-BE11)/BE11 | K11: =(BG11-BF11)/BF11 | L11: =(BH11-BG11)/BG11 | ... U11: =(BQ11-BP11)/BP11 | V11: =AZ11/SUM($AZ11:$BE11) | W11: =BA11/SUM($AZ11:$BE11) | X11: =BB11/SUM($AZ11:$BE11) | Y11: =BC11/SUM($AZ11:$BE11) | Z11: =BD11/SUM($AZ11:$BE11) | AA11: =BE11/SUM($AZ11:$BE11) | AH11: =BL11/SUM($BL11:$BQ11) | AI11: =BM11/SUM($BL11:$BQ11) | AJ11: =BN11/SUM($BL11:$BQ11) | AK11: =BO11/SUM($BL11:$BQ11) | AL11: =BP11/SUM($BL11:$BQ11) | AM11: =BQ11/SUM($BL11:$BQ11) | AZ11: =SUMIFS('25年实际销量'!M:M,'25年实际销量'!$A:$A,$C:$C) | BA11: =SUMIFS('25年实际销量'!N:N,'25年实际销量'!$A:$A,$C:$C) | BB11: =SUMIFS('25年实际销量'!O:O,'25年实际销量'!$A:$A,$C:$C) | BC11: =SUMIFS('25年实际销量'!P:P,'25年实际销量'!$A:$A,$C:$C) | BD11: =SUMIFS('25年实际销量'!Q:Q,'25年实际销量'!$A:$A,$C:$C) | BE11: =SUMIFS('25年实际销量'!R:R,'25年实际销量'!$A:$A,$C:$C) | BF11: =SUMIFS('25年实际销量'!S:S,'25年实际销量'!$A:$A,$C:$C) | BG11: =SUMIFS('25年实际销量'!T:T,'25年实际销量'!$A:$A,$C:$C) | BH11: =SUMIFS('25年实际销量'!U:U,'25年实际销量'!$A:$A,$C:$C) | BI11: =SUMIFS('25年实际销量'!V:V,'25年实际销量'!$A:$A,$C:$C) | BJ11: =SUMIFS('25年实际销量'!W:W,'25年实际销量'!$A:$A,$C:$C) | BK11: =SUMIFS('25年实际销量'!X:X,'25年实际销量'!$A:$A,$C:$C) | BL11: =SUMIFS('26年实际销量'!R:R,'26年实际销量'!$A:$A,$C:$C) | BM11: =SUMIFS('26年实际销量'!S:S,'26年实际销量'!$A:$A,$C:$C) | BN11: =SUMIFS('26年实际销量'!T:T,'26年实际销量'!$A:$A,$C:$C) | BO11: =SUMIFS('26年实际销量'!U:U,'26年实际销量'!$A:$A,$C:$C) | BP11: =SUMIFS('26年实际销量'!V:V,'26年实际销量'!$A:$A,$C:$C) | BQ11: =BS11*0.6+BR11*0.4 | BR11: {=_xlfn.XLOOKUP(C:C,'26年实际销量'!A:A,'26年实际销量'!X:X)} | BS11: 2693 | BT11: =SUM(AZ11:BK11) | BU11: =IF(BT11=0,0,BT11/12) | BV11: =SUM(BL11:BQ11) | BW11: {=_xlfn.XLOOKUP(C:C,'基础销量预测-计划端'!C:C,'基础销量预测-计划端'!AG:AG)} | BX11: =IF(BV11=0,0,BV11/6) | BY11: =ROUND(BL11*($CE$1+1),0) | BZ11: =ROUND(BM11*($CE$1+1),0) | CA11: =ROUND(BN11*($CE$1+1),0) | CB11: =ROUND(BO11*($CE$1+1),0) | CC11: =ROUND(BP11*($CE$1+1),0) | CD11: =ROUND(BQ11*($CE$1+1),0) | CL11: =(AH11*0.7+V11*0.3) | CM11: =(AI11*0.7+W11*0.3) | CN11: =(AJ11*0.7+X11*0.3) | CO11: =(AK11*0.7+Y11*0.3) | CP11: =(AL11*0.7+Z11*0.3) | CQ11: =(AM11*0.7+AA11*0.3)
A12: {=_xlfn.XLOOKUP(C12,'产品基础信息'!B:B,'产品基础信息'!C:C)} | B12: ='产品基础信息'!A11 | C12: ='产品基础信息'!B11 | D12: 0 | E12: =(BA12-AZ12)/AZ12 | F12: =(BB12-BA12)/BA12 | G12: =(BC12-BB12)/BB12 | H12: =(BD12-BC12)/BC12 | I12: =(BE12-BD12)/BD12 | J12: =(BF12-BE12)/BE12 | K12: =(BG12-BF12)/BF12 | L12: =(BH12-BG12)/BG12 | ... U12: =(BQ12-BP12)/BP12 | V12: =AZ12/SUM($AZ12:$BE12) | W12: =BA12/SUM($AZ12:$BE12) | X12: =BB12/SUM($AZ12:$BE12) | Y12: =BC12/SUM($AZ12:$BE12) | Z12: =BD12/SUM($AZ12:$BE12) | AA12: =BE12/SUM($AZ12:$BE12) | AH12: =BL12/SUM($BL12:$BQ12) | AI12: =BM12/SUM($BL12:$BQ12) | AJ12: =BN12/SUM($BL12:$BQ12) | AK12: =BO12/SUM($BL12:$BQ12) | AL12: =BP12/SUM($BL12:$BQ12) | AM12: =BQ12/SUM($BL12:$BQ12) | AZ12: =SUMIFS('25年实际销量'!M:M,'25年实际销量'!$A:$A,$C:$C) | BA12: =SUMIFS('25年实际销量'!N:N,'25年实际销量'!$A:$A,$C:$C) | BB12: =SUMIFS('25年实际销量'!O:O,'25年实际销量'!$A:$A,$C:$C) | BC12: =SUMIFS('25年实际销量'!P:P,'25年实际销量'!$A:$A,$C:$C) | BD12: =SUMIFS('25年实际销量'!Q:Q,'25年实际销量'!$A:$A,$C:$C) | BE12: =SUMIFS('25年实际销量'!R:R,'25年实际销量'!$A:$A,$C:$C) | BF12: =SUMIFS('25年实际销量'!S:S,'25年实际销量'!$A:$A,$C:$C) | BG12: =SUMIFS('25年实际销量'!T:T,'25年实际销量'!$A:$A,$C:$C) | BH12: =SUMIFS('25年实际销量'!U:U,'25年实际销量'!$A:$A,$C:$C) | BI12: =SUMIFS('25年实际销量'!V:V,'25年实际销量'!$A:$A,$C:$C) | BJ12: =SUMIFS('25年实际销量'!W:W,'25年实际销量'!$A:$A,$C:$C) | BK12: =SUMIFS('25年实际销量'!X:X,'25年实际销量'!$A:$A,$C:$C) | BL12: =SUMIFS('26年实际销量'!R:R,'26年实际销量'!$A:$A,$C:$C) | BM12: =SUMIFS('26年实际销量'!S:S,'26年实际销量'!$A:$A,$C:$C) | BN12: =SUMIFS('26年实际销量'!T:T,'26年实际销量'!$A:$A,$C:$C) | BO12: =SUMIFS('26年实际销量'!U:U,'26年实际销量'!$A:$A,$C:$C) | BP12: =SUMIFS('26年实际销量'!V:V,'26年实际销量'!$A:$A,$C:$C) | BQ12: =BS12*0.6+BR12*0.4 | BR12: {=_xlfn.XLOOKUP(C:C,'26年实际销量'!A:A,'26年实际销量'!X:X)} | BS12: 2568 | BT12: =SUM(AZ12:BK12) | BU12: =IF(BT12=0,0,BT12/12) | BV12: =SUM(BL12:BQ12) | BW12: {=_xlfn.XLOOKUP(C:C,'基础销量预测-计划端'!C:C,'基础销量预测-计划端'!AG:AG)} | BX12: =IF(BV12=0,0,BV12/6) | BY12: =ROUND(BL12*($CE$1+1),0) | BZ12: =ROUND(BM12*($CE$1+1),0) | CA12: =ROUND(BN12*($CE$1+1),0) | CB12: =ROUND(BO12*($CE$1+1),0) | CC12: =ROUND(BP12*($CE$1+1),0) | CD12: =ROUND(BQ12*($CE$1+1),0) | CL12: =(AH12*0.7+V12*0.3) | CM12: =(AI12*0.7+W12*0.3) | CN12: =(AJ12*0.7+X12*0.3) | CO12: =(AK12*0.7+Y12*0.3) | CP12: =(AL12*0.7+Z12*0.3) | CQ12: =(AM12*0.7+AA12*0.3)
A13: {=_xlfn.XLOOKUP(C13,'产品基础信息'!B:B,'产品基础信息'!C:C)} | B13: ='产品基础信息'!A12 | C13: ='产品基础信息'!B12 | D13: 0 | E13: =(BA13-AZ13)/AZ13 | F13: =(BB13-BA13)/BA13 | G13: =(BC13-BB13)/BB13 | H13: =(BD13-BC13)/BC13 | I13: =(BE13-BD13)/BD13 | J13: =(BF13-BE13)/BE13 | K13: =(BG13-BF13)/BF13 | L13: =(BH13-BG13)/BG13 | ... U13: =(BQ13-BP13)/BP13 | V13: =AZ13/SUM($AZ13:$BE13) | W13: =BA13/SUM($AZ13:$BE13) | X13: =BB13/SUM($AZ13:$BE13) | Y13: =BC13/SUM($AZ13:$BE13) | Z13: =BD13/SUM($AZ13:$BE13) | AA13: =BE13/SUM($AZ13:$BE13) | AH13: =BL13/SUM($BL13:$BQ13) | AI13: =BM13/SUM($BL13:$BQ13) | AJ13: =BN13/SUM($BL13:$BQ13) | AK13: =BO13/SUM($BL13:$BQ13) | AL13: =BP13/SUM($BL13:$BQ13) | AM13: =BQ13/SUM($BL13:$BQ13) | AZ13: =SUMIFS('25年实际销量'!M:M,'25年实际销量'!$A:$A,$C:$C) | BA13: =SUMIFS('25年实际销量'!N:N,'25年实际销量'!$A:$A,$C:$C) | BB13: =SUMIFS('25年实际销量'!O:O,'25年实际销量'!$A:$A,$C:$C) | BC13: =SUMIFS('25年实际销量'!P:P,'25年实际销量'!$A:$A,$C:$C) | BD13: =SUMIFS('25年实际销量'!Q:Q,'25年实际销量'!$A:$A,$C:$C) | BE13: =SUMIFS('25年实际销量'!R:R,'25年实际销量'!$A:$A,$C:$C) | BF13: =SUMIFS('25年实际销量'!S:S,'25年实际销量'!$A:$A,$C:$C) | BG13: =SUMIFS('25年实际销量'!T:T,'25年实际销量'!$A:$A,$C:$C) | BH13: =SUMIFS('25年实际销量'!U:U,'25年实际销量'!$A:$A,$C:$C) | BI13: =SUMIFS('25年实际销量'!V:V,'25年实际销量'!$A:$A,$C:$C) | BJ13: =SUMIFS('25年实际销量'!W:W,'25年实际销量'!$A:$A,$C:$C) | BK13: =SUMIFS('25年实际销量'!X:X,'25年实际销量'!$A:$A,$C:$C) | BL13: =SUMIFS('26年实际销量'!R:R,'26年实际销量'!$A:$A,$C:$C) | BM13: =SUMIFS('26年实际销量'!S:S,'26年实际销量'!$A:$A,$C:$C) | BN13: =SUMIFS('26年实际销量'!T:T,'26年实际销量'!$A:$A,$C:$C) | BO13: =SUMIFS('26年实际销量'!U:U,'26年实际销量'!$A:$A,$C:$C) | BP13: =SUMIFS('26年实际销量'!V:V,'26年实际销量'!$A:$A,$C:$C) | BQ13: =BS13*0.6+BR13*0.4 | BR13: {=_xlfn.XLOOKUP(C:C,'26年实际销量'!A:A,'26年实际销量'!X:X)} | BS13: 2120 | BT13: =SUM(AZ13:BK13) | BU13: =IF(BT13=0,0,BT13/12) | BV13: =SUM(BL13:BQ13) | BW13: {=_xlfn.XLOOKUP(C:C,'基础销量预测-计划端'!C:C,'基础销量预测-计划端'!AG:AG)} | BX13: =IF(BV13=0,0,BV13/6) | BY13: =ROUND(BL13*($CE$1+1),0) | BZ13: =ROUND(BM13*($CE$1+1),0) | CA13: =ROUND(BN13*($CE$1+1),0) | CB13: =ROUND(BO13*($CE$1+1),0) | CC13: =ROUND(BP13*($CE$1+1),0) | CD13: =ROUND(BQ13*($CE$1+1),0) | CL13: =(AH13*0.7+V13*0.3) | CM13: =(AI13*0.7+W13*0.3) | CN13: =(AJ13*0.7+X13*0.3) | CO13: =(AK13*0.7+Y13*0.3) | CP13: =(AL13*0.7+Z13*0.3) | CQ13: =(AM13*0.7+AA13*0.3)
A14: {=_xlfn.XLOOKUP(C14,'产品基础信息'!B:B,'产品基础信息'!C:C)} | B14: ='产品基础信息'!A13 | C14: ='产品基础信息'!B13 | D14: 0 | E14: =(BA14-AZ14)/AZ14 | F14: =(BB14-BA14)/BA14 | G14: =(BC14-BB14)/BB14 | H14: =(BD14-BC14)/BC14 | I14: =(BE14-BD14)/BD14 | J14: =(BF14-BE14)/BE14 | K14: =(BG14-BF14)/BF14 | L14: =(BH14-BG14)/BG14 | ... U14: =(BQ14-BP14)/BP14 | V14: =AZ14/SUM($AZ14:$BE14) | W14: =BA14/SUM($AZ14:$BE14) | X14: =BB14/SUM($AZ14:$BE14) | Y14: =BC14/SUM($AZ14:$BE14) | Z14: =BD14/SUM($AZ14:$BE14) | AA14: =BE14/SUM($AZ14:$BE14) | AH14: =BL14/SUM($BL14:$BQ14) | AI14: =BM14/SUM($BL14:$BQ14) | AJ14: =BN14/SUM($BL14:$BQ14) | AK14: =BO14/SUM($BL14:$BQ14) | AL14: =BP14/SUM($BL14:$BQ14) | AM14: =BQ14/SUM($BL14:$BQ14) | AZ14: =SUMIFS('25年实际销量'!M:M,'25年实际销量'!$A:$A,$C:$C) | BA14: =SUMIFS('25年实际销量'!N:N,'25年实际销量'!$A:$A,$C:$C) | BB14: =SUMIFS('25年实际销量'!O:O,'25年实际销量'!$A:$A,$C:$C) | BC14: =SUMIFS('25年实际销量'!P:P,'25年实际销量'!$A:$A,$C:$C) | BD14: =SUMIFS('25年实际销量'!Q:Q,'25年实际销量'!$A:$A,$C:$C) | BE14: =SUMIFS('25年实际销量'!R:R,'25年实际销量'!$A:$A,$C:$C) | BF14: =SUMIFS('25年实际销量'!S:S,'25年实际销量'!$A:$A,$C:$C) | BG14: =SUMIFS('25年实际销量'!T:T,'25年实际销量'!$A:$A,$C:$C) | BH14: =SUMIFS('25年实际销量'!U:U,'25年实际销量'!$A:$A,$C:$C) | BI14: =SUMIFS('25年实际销量'!V:V,'25年实际销量'!$A:$A,$C:$C) | BJ14: =SUMIFS('25年实际销量'!W:W,'25年实际销量'!$A:$A,$C:$C) | BK14: =SUMIFS('25年实际销量'!X:X,'25年实际销量'!$A:$A,$C:$C) | BL14: =SUMIFS('26年实际销量'!R:R,'26年实际销量'!$A:$A,$C:$C) | BM14: =SUMIFS('26年实际销量'!S:S,'26年实际销量'!$A:$A,$C:$C) | BN14: =SUMIFS('26年实际销量'!T:T,'26年实际销量'!$A:$A,$C:$C) | BO14: =SUMIFS('26年实际销量'!U:U,'26年实际销量'!$A:$A,$C:$C) | BP14: =SUMIFS('26年实际销量'!V:V,'26年实际销量'!$A:$A,$C:$C) | BQ14: =BS14*0.6+BR14*0.4 | BR14: {=_xlfn.XLOOKUP(C:C,'26年实际销量'!A:A,'26年实际销量'!X:X)} | BS14: 1199 | BT14: =SUM(AZ14:BK14) | BU14: =IF(BT14=0,0,BT14/12) | BV14: =SUM(BL14:BQ14) | BW14: {=_xlfn.XLOOKUP(C:C,'基础销量预测-计划端'!C:C,'基础销量预测-计划端'!AG:AG)} | BX14: =IF(BV14=0,0,BV14/6) | BY14: =ROUND(BL14*($CE$1+1),0) | BZ14: =ROUND(BM14*($CE$1+1),0) | CA14: =ROUND(BN14*($CE$1+1),0) | CB14: =ROUND(BO14*($CE$1+1),0) | CC14: =ROUND(BP14*($CE$1+1),0) | CD14: =ROUND(BQ14*($CE$1+1),0) | CL14: =(AH14*0.7+V14*0.3) | CM14: =(AI14*0.7+W14*0.3) | CN14: =(AJ14*0.7+X14*0.3) | CO14: =(AK14*0.7+Y14*0.3) | CP14: =(AL14*0.7+Z14*0.3) | CQ14: =(AM14*0.7+AA14*0.3)
